Workbook

Sheet REVENUE ASSUMPTIONS
B1: FINANCIAL MODEL FOR START UP | D1: Revenue Assumption
D4: 46048 | E4: =EDATE(D4,1) -> 46079 | F4: =EDATE(E4,1) -> 46107 | G4: =EDATE(F4,1) -> 46138 | H4: =EDATE(G4,1) -> 46168 | I4: =EDATE(H4,1) -> 46199 | J4: =EDATE(I4,1) -> 46229 | K4: =EDATE(J4,1) -> 46260 | L4: =EDATE(K4,1) -> 46291 | ... AA4: =EDATE(Z4,1) -> 46747
B5: Assumptions | C5: Unit | D5: Month 1 | E5: Month 2 | F5: Month 3 | G5: Month 4 | H5: Month 5 | I5: Month 6 | J5: Month 7 | K5: Month 8 | L5: Month 9 | M5: Month 10 | N5: Month 11 | O5: Month 12 | P5: Month 13 | Q5: Month 14 | R5: Month 15 | S5: Month 16 | T5: Month 17 | U5: Month 18 | V5: Month 19 | W5: Month 20 | X5: Month 21 | Y5: Month 22 | Z5: Month 23 | AA5: Month 24
B6: Revenue Assumptions | D6: Best Case
B8: Page Traffic
B9: Organic | C9: # | D9: 20000 | E9: =D$9+500 -> 20500 | F9: =E$9+500 -> 21000 | G9: =F$9+500 -> 21500 | H9: =G$9+500 -> 22000 | I9: =H$9+500 -> 22500 | J9: =I$9+500 -> 23000 | K9: =J$9+500 -> 23500 | L9: =K$9+500 -> 24000 | ... AA9: =Z$9+500 -> 31500
B10: Paid | C10: # | D10: 5000 | E10: =D$10+100 -> 5100 | F10: =E$10+100 -> 5200 | G10: =F$10+100 -> 5300 | H10: =G$10+100 -> 5400 | I10: =H$10+100 -> 5500 | J10: =I$10+100 -> 5600 | K10: =J$10+100 -> 5700 | L10: =K$10+100 -> 5800 | ... AA10: =Z$10+100 -> 7300
B11: Total Traffic | C11: # | D11: =SUM(D9:D10) -> 25000 | E11: =SUM(E9:E10) -> 25600 | F11: =SUM(F9:F10) -> 26200 | G11: =SUM(G9:G10) -> 26800 | H11: =SUM(H9:H10) -> 27400 | I11: =SUM(I9:I10) -> 28000 | J11: =SUM(J9:J10) -> 28600 | K11: =SUM(K9:K10) -> 29200 | ... AA11: =SUM(AA9:AA10) -> 38800
B13: Conversion Rate
B14: Organic | C14: % | D14: 0.03 | E14: 0.031 | F14: 0.031 | G14: 0.031 | H14: 0.032 | I14: 0.032 | J14: 0.032 | K14: 0.033 | L14: 0.033 | M14: 0.033 | N14: 0.034 | O14: 0.034 | P14: 0.034 | Q14: 0.035 | R14: 0.035 | S14: 0.035 | T14: 0.036 | U14: 0.036 | V14: 0.036 | W14: 0.037 | X14: 0.037 | Y14: 0.037 | Z14: 0.038 | AA14: 0.038
B15: Paid | C15: % | D15: 0.02 | E15: 0.021 | F15: 0.021 | G15: 0.021 | H15: 0.022 | I15: 0.022 | J15: 0.022 | K15: 0.023 | L15: 0.023 | M15: 0.023 | N15: 0.024 | O15: 0.024 | P15: 0.024 | Q15: 0.025 | R15: 0.025 | S15: 0.025 | T15: 0.026 | U15: 0.026 | V15: 0.026 | W15: 0.027 | X15: 0.027 | Y15: 0.027 | Z15: 0.028 | AA15: 0.028
B16: Average Conversion | C16: % | D16: =AVERAGE(D14,D15) -> 0.025 | E16: =AVERAGE(E14,E15) -> 0.026 | F16: =AVERAGE(F14,F15) -> 0.026 | G16: =AVERAGE(G14,G15) -> 0.026 | H16: =AVERAGE(H14,H15) -> 0.027 | I16: =AVERAGE(I14,I15) -> 0.027 | J16: =AVERAGE(J14,J15) -> 0.027 | K16: =AVERAGE(K14,K15) -> 0.028 | ... AA16: =AVERAGE(AA14,AA15) -> 0.033
B18: Orders
B20: Organic | C20: # | D20: =D9*D14 -> 600 | E20: =E9*E14 -> 635.5 | F20: =F9*F14 -> 651 | G20: =G9*G14 -> 666.5 | H20: =H9*H14 -> 704 | I20: =I9*I14 -> 720 | J20: =J9*J14 -> 736 | K20: =K9*K14 -> 775.5 | ... AA20: =AA9*AA14 -> 1197
B21: Paid | C21: # | D21: =D10*D15 -> 100 | E21: =E10*E15 -> 107.1 | F21: =F10*F15 -> 109.2 | G21: =G10*G15 -> 111.3 | H21: =H10*H15 -> 118.8 | I21: =I10*I15 -> 121 | J21: =J10*J15 -> 123.2 | K21: =K10*K15 -> 131.1 | ... AA21: =AA10*AA15 -> 204.4
B22: Total Orders | C22: # | D22: =SUM(D20:D21) -> 700 | E22: =SUM(E20:E21) -> 742.6 | F22: =SUM(F20:F21) -> 760.2 | G22: =SUM(G20:G21) -> 777.8 | H22: =SUM(H20:H21) -> 822.8 | I22: =SUM(I20:I21) -> 841 | J22: =SUM(J20:J21) -> 859.2 | K22: =SUM(K20:K21) -> 906.6 | ... AA22: =SUM(AA20:AA21) -> 1401.4
B24: Order Details
B26: Average Item Value | C26: ₹ | D26: 50 | E26: 50 | F26: 50 | G26: 50 | H26: 50 | I26: 50 | J26: 51 | K26: 51 | L26: 51 | M26: 51 | N26: 51 | O26: 51 | P26: 52 | Q26: 52 | R26: 52 | S26: 52 | T26: 52 | U26: 52 | V26: 53 | W26: 53 | X26: 53 | Y26: 53 | Z26: 53 | AA26: 53
B27: # of Items per Order | C27: # | D27: 1 | E27: 1 | F27: 1 | G27: 1 | H27: 1 | I27: 1 | J27: 1 | K27: 1 | L27: 1 | M27: 2 | N27: 2 | O27: 2 | P27: 2 | Q27: 2 | R27: 2 | S27: 2 | T27: 2 | U27: 2 | V27: 3 | W27: 3 | X27: 3 | Y27: 3 | Z27: 3 | AA27: 3
B28: Average Order Value | C28: ₹ | D28: =D26*D27 -> 50 | E28: =E26*E27 -> 50 | F28: =F26*F27 -> 50 | G28: =G26*G27 -> 50 | H28: =H26*H27 -> 50 | I28: =I26*I27 -> 50 | J28: =J26*J27 -> 51 | K28: =K26*K27 -> 51 | ... AA28: =AA26*AA27 -> 159
B30: Revenue Assumptions | D30: Base Case
B32: Page Traffic
B33: Organic | C33: # | D33: 20000 | E33: =D$33+400 -> 20400 | F33: =E$33+400 -> 20800 | G33: =F$33+400 -> 21200 | H33: =G$33+400 -> 21600 | I33: =H$33+400 -> 22000 | J33: =I$33+400 -> 22400 | K33: =J$33+400 -> 22800 | L33: =K$33+400 -> 23200 | ... AA33: =Z$33+400 -> 29200
B34: Paid | C34: # | D34: 5000 | E34: =D$34+200 -> 5200 | F34: =E$34+200 -> 5400 | G34: =F$34+200 -> 5600 | H34: =G$34+200 -> 5800 | I34: =H$34+200 -> 6000 | J34: =I$34+200 -> 6200 | K34: =J$34+200 -> 6400 | L34: =K$34+200 -> 6600 | ... AA34: =Z$34+200 -> 9600
B35: Total Traffic | C35: # | D35: =SUM(D33:D34) -> 25000 | E35: =SUM(E33:E34) -> 25600 | F35: =SUM(F33:F34) -> 26200 | G35: =SUM(G33:G34) -> 26800 | H35: =SUM(H33:H34) -> 27400 | I35: =SUM(I33:I34) -> 28000 | J35: =SUM(J33:J34) -> 28600 | K35: =SUM(K33:K34) -> 29200 | ... AA35: =SUM(AA33:AA34) -> 38800
B37: Conversion Rate
B38: Organic | C38: % | D38: 0.02 | E38: 0.021 | F38: 0.021 | G38: 0.021 | H38: 0.022 | I38: 0.022 | J38: 0.022 | K38: 0.023 | L38: 0.023 | M38: 0.023 | N38: 0.024 | O38: 0.024 | P38: 0.024 | Q38: 0.025 | R38: 0.025 | S38: 0.025 | T38: 0.026 | U38: 0.026 | V38: 0.026 | W38: 0.027 | X38: 0.027 | Y38: 0.027 | Z38: 0.028 | AA38: 0.028
B39: Paid | C39: % | D39: 0.01 | E39: 0.011 | F39: 0.011 | G39: 0.011 | H39: 0.012 | I39: 0.012 | J39: 0.012 | K39: 0.013 | L39: 0.013 | M39: 0.013 | N39: 0.014 | O39: 0.014 | P39: 0.014 | Q39: 0.015 | R39: 0.015 | S39: 0.015 | T39: 0.016 | U39: 0.016 | V39: 0.016 | W39: 0.017 | X39: 0.017 | Y39: 0.017 | Z39: 0.018 | AA39: 0.018
B40: Average Conversion | C40: % | D40: =AVERAGE(D38,D39) -> 0.015 | E40: =AVERAGE(E38,E39) -> 0.016 | F40: =AVERAGE(F38,F39) -> 0.016 | G40: =AVERAGE(G38,G39) -> 0.016 | H40: =AVERAGE(H38,H39) -> 0.017 | I40: =AVERAGE(I38,I39) -> 0.017 | J40: =AVERAGE(J38,J39) -> 0.017 | K40: =AVERAGE(K38,K39) -> 0.018 | ... AA40: =AVERAGE(AA38,AA39) -> 0.023
B42: Orders
B44: Organic | C44: # | D44: =D33*D38 -> 400 | E44: =E33*E38 -> 428.4 | F44: =F33*F38 -> 436.8 | G44: =G33*G38 -> 445.2 | H44: =H33*H38 -> 475.2 | I44: =I33*I38 -> 484 | J44: =J33*J38 -> 492.8 | K44: =K33*K38 -> 524.4 | ... AA44: =AA33*AA38 -> 817.6
B45: Paid | C45: # | D45: =D34*D39 -> 50 | E45: =E34*E39 -> 57.2 | F45: =F34*F39 -> 59.4 | G45: =G34*G39 -> 61.6 | H45: =H34*H39 -> 69.6 | I45: =I34*I39 -> 72 | J45: =J34*J39 -> 74.4 | K45: =K34*K39 -> 83.2 | ... AA45: =AA34*AA39 -> 172.8
B46: Total Orders | C46: # | D46: =SUM(D44:D45) -> 450 | E46: =SUM(E44:E45) -> 485.6 | F46: =SUM(F44:F45) -> 496.2 | G46: =SUM(G44:G45) -> 506.8 | H46: =SUM(H44:H45) -> 544.8 | I46: =SUM(I44:I45) -> 556 | J46: =SUM(J44:J45) -> 567.2 | K46: =SUM(K44:K45) -> 607.6 | ... AA46: =SUM(AA44:AA45) -> 990.4
B48: Order Details
B50: Average Item Value | C50: ₹ | D50: 100 | E50: 100 | F50: 100 | G50: 100 | H50: 100 | I50: 100 | J50: 100 | K50: 100 | L50: 100 | M50: 100 | N50: 100 | O50: 100 | P50: 102 | Q50: 102 | R50: 102 | S50: 102 | T50: 102 | U50: 102 | V50: 102 | W50: 102 | X50: 102 | Y50: 102 | Z50: 102 | AA50: 102
B51: # of Items per Order | C51: # | D51: 1 | E51: 1 | F51: 1 | G51: 1 | H51: 1 | I51: 1 | J51: 1 | K51: 1 | L51: 1 | M51: 1 | N51: 1 | O51: 1 | P51: 2 | Q51: 2 | R51: 2 | S51: 2 | T51: 2 | U51: 2 | V51: 2 | W51: 2 | X51: 2 | Y51: 2 | Z51: 2 | AA51: 2
B52: Average Order Value | C52: ₹ | D52: =D50*D51 -> 100 | E52: =E50*E51 -> 100 | F52: =F50*F51 -> 100 | G52: =G50*G51 -> 100 | H52: =H50*H51 -> 100 | I52: =I50*I51 -> 100 | J52: =J50*J51 -> 100 | K52: =K50*K51 -> 100 | ... AA52: =AA50*AA51 -> 204
B54: Revenue Assumptions | D54: Worst Case
B56: Page Traffic
B57: Organic | C57: # | D57: 20000 | E57: =D$57+300 -> 20300 | F57: =E$57+300 -> 20600 | G57: =F$57+300 -> 20900 | H57: =G$57+300 -> 21200 | I57: =H$57+300 -> 21500 | J57: =I$57+300 -> 21800 | K57: =J$57+300 -> 22100 | L57: =K$57+300 -> 22400 | ... AA57: =Z$57+300 -> 26900
...

Sheet COST ASSUMPTIONS
B1: FINANCIAL MODEL FOR START UP | D1: Cost Assumption
D4: ='REVENUE ASSUMPTIONS'!D$4 -> 46048 | E4: ='REVENUE ASSUMPTIONS'!E$4 -> 46079 | F4: ='REVENUE ASSUMPTIONS'!F$4 -> 46107 | G4: ='REVENUE ASSUMPTIONS'!G$4 -> 46138 | H4: ='REVENUE ASSUMPTIONS'!H$4 -> 46168 | I4: ='REVENUE ASSUMPTIONS'!I$4 -> 46199 | J4: ='REVENUE ASSUMPTIONS'!J$4 -> 46229 | K4: ='REVENUE ASSUMPTIONS'!K$4 -> 46260 | ... AA4: ='REVENUE ASSUMPTIONS'!AA$4 -> 46747
B5: Assumptions | C5: Unit | D5: ='REVENUE ASSUMPTIONS'!D$5 -> Month 1 | E5: ='REVENUE ASSUMPTIONS'!E$5 -> Month 2 | F5: ='REVENUE ASSUMPTIONS'!F$5 -> Month 3 | G5: ='REVENUE ASSUMPTIONS'!G$5 -> Month 4 | H5: ='REVENUE ASSUMPTIONS'!H$5 -> Month 5 | I5: ='REVENUE ASSUMPTIONS'!I$5 -> Month 6 | J5: ='REVENUE ASSUMPTIONS'!J$5 -> Month 7 | K5: ='REVENUE ASSUMPTIONS'!K$5 -> Month 8 | ... AA5: ='REVENUE ASSUMPTIONS'!AA$5 -> Month 24
B6: Cost Assumptions | D6: Best Case
B8: Variable
B10: Manufacturing (Per Order) | C10: ₹ | D10: 12 | E10: 12 | F10: 12 | G10: 12 | H10: 12 | I10: 12 | J10: 11 | K10: 11 | L10: 11 | M10: 11 | N10: 11 | O10: 11 | P10: 11 | Q10: 11 | R10: 11 | S10: 11 | T10: 11 | U10: 11 | V10: 10 | W10: 10 | X10: 10 | Y10: 10 | Z10: 10 | AA10: 10
B11: Order Fulfillment (Per Order) | C11: ₹ | D11: 5 | E11: 5 | F11: 5 | G11: 5 | H11: 5 | I11: 5 | J11: 3 | K11: 3 | L11: 3 | M11: 3 | N11: 3 | O11: 3 | P11: 3 | Q11: 3 | R11: 3 | S11: 3 | T11: 3 | U11: 3 | V11: 2 | W11: 2 | X11: 2 | Y11: 2 | Z11: 2 | AA11: 2
B12: Paid Traffic (Cost per Paid Click) | C12: ₹ | D12: 3 | E12: 3 | F12: 3 | G12: 3 | H12: 3 | I12: 3 | J12: 3 | K12: 3 | L12: 3 | M12: 3 | N12: 3 | O12: 3 | P12: 2 | Q12: 2 | R12: 2 | S12: 2 | T12: 2 | U12: 2 | V12: 2 | W12: 2 | X12: 2 | Y12: 2 | Z12: 2 | AA12: 2
B14: Fixed
B16: Warehouse Rent | C16: ₹ | D16: 10000 | E16: 10000 | F16: 10000 | G16: 10000 | H16: 10000 | I16: 10000 | J16: 10000 | K16: 10000 | L16: 10000 | M16: 10000 | N16: 10000 | O16: 10000 | P16: 12000 | Q16: 12000 | R16: 12000 | S16: 12000 | T16: 12000 | U16: 12000 | V16: 12000 | W16: 12000 | X16: 12000 | Y16: 12000 | Z16: 12000 | AA16: 12000
B17: Office Rent | C17: ₹ | D17: 20000 | E17: 20000 | F17: 20000 | G17: 20000 | H17: 20000 | I17: 20000 | J17: 20000 | K17: 20000 | L17: 20000 | M17: 20000 | N17: 20000 | O17: 20000 | P17: 22000 | Q17: 22000 | R17: 22000 | S17: 22000 | T17: 22000 | U17: 22000 | V17: 22000 | W17: 22000 | X17: 22000 | Y17: 22000 | Z17: 22000 | AA17: 22000
B18: Salaries | C18: ₹ | D18: 30000 | E18: 30000 | F18: 30000 | G18: 30000 | H18: 30000 | I18: 30000 | J18: 30000 | K18: 30000 | L18: 30000 | M18: 30000 | N18: 30000 | O18: 30000 | P18: 32000 | Q18: 32000 | R18: 32000 | S18: 32000 | T18: 32000 | U18: 32000 | V18: 32000 | W18: 32000 | X18: 32000 | Y18: 32000 | Z18: 32000 | AA18: 32000
B19: Other | C19: ₹ | D19: 2000 | E19: 2000 | F19: 2000 | G19: 2000 | H19: 2000 | I19: 2000 | J19: 2000 | K19: 2000 | L19: 2000 | M19: 2000 | N19: 2000 | O19: 2000 | P19: 2200 | Q19: 2200 | R19: 2200 | S19: 2200 | T19: 2200 | U19: 2200 | V19: 2200 | W19: 2200 | X19: 2200 | Y19: 2200 | Z19: 2200 | AA19: 2200
B21: Tax Rate | C21: % | D21: 0.25 | E21: 0.25 | F21: 0.25 | G21: 0.25 | H21: 0.25 | I21: 0.25 | J21: 0.25 | K21: 0.25 | L21: 0.25 | M21: 0.25 | N21: 0.25 | O21: 0.25 | P21: 0.25 | Q21: 0.25 | R21: 0.25 | S21: 0.25 | T21: 0.25 | U21: 0.25 | V21: 0.25 | W21: 0.25 | X21: 0.25 | Y21: 0.25 | Z21: 0.25 | AA21: 0.25
B23: Cost Assumptions | D23: Base Case
B25: Variable
B27: Manufacturing (Per Order) | C27: ₹ | D27: 12 | E27: 12 | F27: 12 | G27: 12 | H27: 12 | I27: 12 | J27: 12 | K27: 12 | L27: 12 | M27: 12 | N27: 12 | O27: 12 | P27: 11 | Q27: 11 | R27: 11 | S27: 11 | T27: 11 | U27: 11 | V27: 11 | W27: 11 | X27: 11 | Y27: 11 | Z27: 11 | AA27: 11
B28: Order Fulfillment (Per Order) | C28: ₹ | D28: 5 | E28: 5 | F28: 5 | G28: 5 | H28: 5 | I28: 5 | J28: 4 | K28: 4 | L28: 4 | M28: 4 | N28: 4 | O28: 4 | P28: 4 | Q28: 4 | R28: 4 | S28: 4 | T28: 4 | U28: 4 | V28: 3 | W28: 3 | X28: 3 | Y28: 3 | Z28: 3 | AA28: 3
B29: Paid Traffic (Cost per Paid Click) | C29: ₹ | D29: 4 | E29: 4 | F29: 4 | G29: 4 | H29: 4 | I29: 4 | J29: 4 | K29: 4 | L29: 4 | M29: 4 | N29: 4 | O29: 4 | P29: 3 | Q29: 3 | R29: 3 | S29: 3 | T29: 3 | U29: 3 | V29: 3 | W29: 3 | X29: 3 | Y29: 3 | Z29: 3 | AA29: 3
B31: Fixed
B33: Warehouse Rent | C33: ₹ | D33: 12000 | E33: 12000 | F33: 12000 | G33: 12000 | H33: 12000 | I33: 12000 | J33: 12000 | K33: 12000 | L33: 12000 | M33: 12000 | N33: 12000 | O33: 12000 | P33: 13000 | Q33: 13000 | R33: 13000 | S33: 13000 | T33: 13000 | U33: 13000 | V33: 13000 | W33: 13000 | X33: 13000 | Y33: 13000 | Z33: 13000 | AA33: 13000
B34: Office Rent | C34: ₹ | D34: 22000 | E34: 22000 | F34: 22000 | G34: 22000 | H34: 22000 | I34: 22000 | J34: 22000 | K34: 22000 | L34: 22000 | M34: 22000 | N34: 22000 | O34: 22000 | P34: 23000 | Q34: 23000 | R34: 23000 | S34: 23000 | T34: 23000 | U34: 23000 | V34: 23000 | W34: 23000 | X34: 23000 | Y34: 23000 | Z34: 23000 | AA34: 23000
B35: Salaries | C35: ₹ | D35: 32000 | E35: 32000 | F35: 32000 | G35: 32000 | H35: 32000 | I35: 32000 | J35: 32000 | K35: 32000 | L35: 32000 | M35: 32000 | N35: 32000 | O35: 32000 | P35: 33000 | Q35: 33000 | R35: 33000 | S35: 33000 | T35: 33000 | U35: 33000 | V35: 33000 | W35: 33000 | X35: 33000 | Y35: 33000 | Z35: 33000 | AA35: 33000
B36: Other | C36: ₹ | D36: 2200 | E36: 2200 | F36: 2200 | G36: 2200 | H36: 2200 | I36: 2200 | J36: 2200 | K36: 2200 | L36: 2200 | M36: 2200 | N36: 2200 | O36: 2200 | P36: 2300 | Q36: 2300 | R36: 2300 | S36: 2300 | T36: 2300 | U36: 2300 | V36: 2300 | W36: 2300 | X36: 2300 | Y36: 2300 | Z36: 2300 | AA36: 2300
B38: Tax Rate | C38: % | D38: 0.25 | E38: 0.25 | F38: 0.25 | G38: 0.25 | H38: 0.25 | I38: 0.25 | J38: 0.25 | K38: 0.25 | L38: 0.25 | M38: 0.25 | N38: 0.25 | O38: 0.25 | P38: 0.25 | Q38: 0.25 | R38: 0.25 | S38: 0.25 | T38: 0.25 | U38: 0.25 | V38: 0.25 | W38: 0.25 | X38: 0.25 | Y38: 0.25 | Z38: 0.25 | AA38: 0.25
B40: Cost Assumptions | D40: Worst Case
B42: Variable
B44: Manufacturing (Per Order) | C44: ₹ | D44: 12 | E44: 12 | F44: 12 | G44: 12 | H44: 12 | I44: 12 | J44: 12 | K44: 13 | L44: 13 | M44: 13 | N44: 13 | O44: 13 | P44: 12 | Q44: 12 | R44: 12 | S44: 12 | T44: 12 | U44: 12 | V44: 12 | W44: 12 | X44: 12 | Y44: 12 | Z44: 12 | AA44: 12
B45: Order Fulfillment (Per Order) | C45: ₹ | D45: 5 | E45: 5 | F45: 5 | G45: 5 | H45: 5 | I45: 5 | J45: 5 | K45: 5 | L45: 5 | M45: 5 | N45: 5 | O45: 5 | P45: 5 | Q45: 5 | R45: 5 | S45: 5 | T45: 5 | U45: 5 | V45: 4 | W45: 4 | X45: 4 | Y45: 4 | Z45: 4 | AA45: 4
B46: Paid Traffic (Cost per Paid Click) | C46: ₹ | D46: 5 | E46: 5 | F46: 5 | G46: 5 | H46: 5 | I46: 5 | J46: 5 | K46: 5 | L46: 5 | M46: 5 | N46: 5 | O46: 5 | P46: 4 | Q46: 4 | R46: 4 | S46: 4 | T46: 4 | U46: 4 | V46: 4 | W46: 4 | X46: 4 | Y46: 4 | Z46: 4 | AA46: 4
B48: Fixed
B50: Warehouse Rent | C50: ₹ | D50: 14000 | E50: 14000 | F50: 14000 | G50: 14000 | H50: 14000 | I50: 14000 | J50: 14000 | K50: 14000 | L50: 14000 | M50: 14000 | N50: 14000 | O50: 14000 | P50: 16000 | Q50: 16000 | R50: 16000 | S50: 16000 | T50: 16000 | U50: 16000 | V50: 16000 | W50: 16000 | X50: 16000 | Y50: 16000 | Z50: 16000 | AA50: 16000
B51: Office Rent | C51: ₹ | D51: 24000 | E51: 24000 | F51: 24000 | G51: 24000 | H51: 24000 | I51: 24000 | J51: 24000 | K51: 24000 | L51: 24000 | M51: 24000 | N51: 24000 | O51: 24000 | P51: 26000 | Q51: 26000 | R51: 26000 | S51: 26000 | T51: 26000 | U51: 26000 | V51: 26000 | W51: 26000 | X51: 26000 | Y51: 26000 | Z51: 26000 | AA51: 26000
B52: Salaries | C52: ₹ | D52: 34000 | E52: 34000 | F52: 34000 | G52: 34000 | H52: 34000 | I52: 34000 | J52: 34000 | K52: 34000 | L52: 34000 | M52: 34000 | N52: 34000 | O52: 34000 | P52: 36000 | Q52: 36000 | R52: 36000 | S52: 36000 | T52: 36000 | U52: 36000 | V52: 36000 | W52: 36000 | X52: 36000 | Y52: 36000 | Z52: 36000 | AA52: 36000
B53: Other | C53: ₹ | D53: 3000 | E53: 3000 | F53: 3000 | G53: 3000 | H53: 3000 | I53: 3000 | J53: 3000 | K53: 3000 | L53: 3000 | M53: 3000 | N53: 3000 | O53: 3000 | P53: 3000 | Q53: 3000 | R53: 3000 | S53: 3000 | T53: 3000 | U53: 3000 | V53: 3000 | W53: 3000 | X53: 3000 | Y53: 3000 | Z53: 3000 | AA53: 3000
B55: Tax Rate | C55: % | D55: 0.25 | E55: 0.25 | F55: 0.25 | G55: 0.25 | H55: 0.25 | I55: 0.25 | J55: 0.25 | K55: 0.25 | L55: 0.25 | M55: 0.25 | N55: 0.25 | O55: 0.25 | P55: 0.25 | Q55: 0.25 | R55: 0.25 | S55: 0.25 | T55: 0.25 | U55: 0.25 | V55: 0.25 | W55: 0.25 | X55: 0.25 | Y55: 0.25 | Z55: 0.25 | AA55: 0.25
C57: Best Case Variable Cost | P57: Best Case Fixed Cost
B59: Variable Cost: Variable costs scale efficiently with higher volumes due to operational efficiencies and improved cost control. Per-unit costs remain stable or decline as scale benefits are realized. Fixed Cost: Fixed costs remain largely stable, reflecting disciplined expense management. Revenue growth creates strong operating leverage over time.
C76: Base Case Variable Cost | P76: Base Case Fixed Cost
B78: Variable Cost: Variable costs increase proportionately with sales growth under normal operating conditions. Cost behavior remains predictable without major efficiency gains or overruns. Fixed Cost: Fixed costs rise gradually due to normal increases in rent, salaries, and overheads. Overall cost levels remain aligned with business growth.
...

Sheet INCOME STATEMENT
B1: FINANCIAL MODEL FOR START UP | D1: Income Statement
D4: ='REVENUE ASSUMPTIONS'!D$4 -> 46048 | E4: ='REVENUE ASSUMPTIONS'!E$4 -> 46079 | F4: ='REVENUE ASSUMPTIONS'!F$4 -> 46107 | G4: ='REVENUE ASSUMPTIONS'!G$4 -> 46138 | H4: ='REVENUE ASSUMPTIONS'!H$4 -> 46168 | I4: ='REVENUE ASSUMPTIONS'!I$4 -> 46199 | J4: ='REVENUE ASSUMPTIONS'!J$4 -> 46229 | K4: ='REVENUE ASSUMPTIONS'!K$4 -> 46260 | ... AA4: ='REVENUE ASSUMPTIONS'!AA$4 -> 46747
B5: Assumptions | C5: Unit | D5: ='REVENUE ASSUMPTIONS'!D$5 -> Month 1 | E5: ='REVENUE ASSUMPTIONS'!E$5 -> Month 2 | F5: ='REVENUE ASSUMPTIONS'!F$5 -> Month 3 | G5: ='REVENUE ASSUMPTIONS'!G$5 -> Month 4 | H5: ='REVENUE ASSUMPTIONS'!H$5 -> Month 5 | I5: ='REVENUE ASSUMPTIONS'!I$5 -> Month 6 | J5: ='REVENUE ASSUMPTIONS'!J$5 -> Month 7 | K5: ='REVENUE ASSUMPTIONS'!K$5 -> Month 8 | ... AA5: ='REVENUE ASSUMPTIONS'!AA$5 -> Month 24
B6: Income Statement | D6: Choose case scenario for better visualization | P6: 2
B8: Revenue | C8: ₹ | D8: =CHOOSE($P$6,'REVENUE ASSUMPTIONS'!D$28*'REVENUE ASSUMPTIONS'!D$22,'REVENUE ASSUMPTIONS'!D$52*'REVENUE ASSUMPTIONS'!D$46,'REVENUE ASSUMPTIONS'!D$76*'REVENUE ASSUMPTIONS'!D$70) -> 45000 | E8: =CHOOSE($P$6,'REVENUE ASSUMPTIONS'!E$28*'REVENUE ASSUMPTIONS'!E$22,'REVENUE ASSUMPTIONS'!E$52*'REVENUE ASSUMPTIONS'!E$46,'REVENUE ASSUMPTIONS'!E$76*'REVENUE ASSUMPTIONS'!E$70) -> 48560 | F8: =CHOOSE($P$6,'REVENUE ASSUMPTIONS'!F$28*'REVENUE ASSUMPTIONS'!F$22,'REVENUE ASSUMPTIONS'!F$52*'REVENUE ASSUMPTIONS'!F$46,'REVENUE ASSUMPTIONS'!F$76*'REVENUE ASSUMPTIONS'!F$70) -> 49620 | G8: =CHOOSE($P$6,'REVENUE ASSUMPTIONS'!G$28*'REVENUE ASSUMPTIONS'!G$22,'REVENUE ASSUMPTIONS'!G$52*'REVENUE ASSUMPTIONS'!G$46,'REVENUE ASSUMPTIONS'!G$76*'REVENUE ASSUMPTIONS'!G$70) -> 50680 | H8: =CHOOSE($P$6,'REVENUE ASSUMPTIONS'!H$28*'REVENUE ASSUMPTIONS'!H$22,'REVENUE ASSUMPTIONS'!H$52*'REVENUE ASSUMPTIONS'!H$46,'REVENUE ASSUMPTIONS'!H$76*'REVENUE ASSUMPTIONS'!H$70) -> 54480 | I8: =CHOOSE($P$6,'REVENUE ASSUMPTIONS'!I$28*'REVENUE ASSUMPTIONS'!I$22,'REVENUE ASSUMPTIONS'!I$52*'REVENUE ASSUMPTIONS'!I$46,'REVENUE ASSUMPTIONS'!I$76*'REVENUE ASSUMPTIONS'!I$70) -> 55600 | J8: =CHOOSE($P$6,'REVENUE ASSUMPTIONS'!J$28*'REVENUE ASSUMPTIONS'!J$22,'REVENUE ASSUMPTIONS'!J$52*'REVENUE ASSUMPTIONS'!J$46,'REVENUE ASSUMPTIONS'!J$76*'REVENUE ASSUMPTIONS'!J$70) -> 56720 | K8: =CHOOSE($P$6,'REVENUE ASSUMPTIONS'!K$28*'REVENUE ASSUMPTIONS'!K$22,'REVENUE ASSUMPTIONS'!K$52*'REVENUE ASSUMPTIONS'!K$46,'REVENUE ASSUMPTIONS'!K$76*'REVENUE ASSUMPTIONS'!K$70) -> 60760 | ... AA8: =CHOOSE($P$6,'REVENUE ASSUMPTIONS'!AA$28*'REVENUE ASSUMPTIONS'!AA$22,'REVENUE ASSUMPTIONS'!AA$52*'REVENUE ASSUMPTIONS'!AA$46,'REVENUE ASSUMPTIONS'!AA$76*'REVENUE ASSUMPTIONS'!AA$70) -> 202041.6
B9: COGS | C9: ₹ | D9: =CHOOSE($P$6,'COST ASSUMPTIONS'!D$10*'REVENUE ASSUMPTIONS'!D$22,'REVENUE ASSUMPTIONS'!D$46*'COST ASSUMPTIONS'!D$27,'COST ASSUMPTIONS'!D$44*'REVENUE ASSUMPTIONS'!D$70) -> 5400 | E9: =CHOOSE($P$6,'COST ASSUMPTIONS'!E$10*'REVENUE ASSUMPTIONS'!E$22,'REVENUE ASSUMPTIONS'!E$46*'COST ASSUMPTIONS'!E$27,'COST ASSUMPTIONS'!E$44*'REVENUE ASSUMPTIONS'!E$70) -> 5827.2 | F9: =CHOOSE($P$6,'COST ASSUMPTIONS'!F$10*'REVENUE ASSUMPTIONS'!F$22,'REVENUE ASSUMPTIONS'!F$46*'COST ASSUMPTIONS'!F$27,'COST ASSUMPTIONS'!F$44*'REVENUE ASSUMPTIONS'!F$70) -> 5954.4 | G9: =CHOOSE($P$6,'COST ASSUMPTIONS'!G$10*'REVENUE ASSUMPTIONS'!G$22,'REVENUE ASSUMPTIONS'!G$46*'COST ASSUMPTIONS'!G$27,'COST ASSUMPTIONS'!G$44*'REVENUE ASSUMPTIONS'!G$70) -> 6081.6 | H9: =CHOOSE($P$6,'COST ASSUMPTIONS'!H$10*'REVENUE ASSUMPTIONS'!H$22,'REVENUE ASSUMPTIONS'!H$46*'COST ASSUMPTIONS'!H$27,'COST ASSUMPTIONS'!H$44*'REVENUE ASSUMPTIONS'!H$70) -> 6537.6 | I9: =CHOOSE($P$6,'COST ASSUMPTIONS'!I$10*'REVENUE ASSUMPTIONS'!I$22,'REVENUE ASSUMPTIONS'!I$46*'COST ASSUMPTIONS'!I$27,'COST ASSUMPTIONS'!I$44*'REVENUE ASSUMPTIONS'!I$70) -> 6672 | J9: =CHOOSE($P$6,'COST ASSUMPTIONS'!J$10*'REVENUE ASSUMPTIONS'!J$22,'REVENUE ASSUMPTIONS'!J$46*'COST ASSUMPTIONS'!J$27,'COST ASSUMPTIONS'!J$44*'REVENUE ASSUMPTIONS'!J$70) -> 6806.4 | K9: =CHOOSE($P$6,'COST ASSUMPTIONS'!K$10*'REVENUE ASSUMPTIONS'!K$22,'REVENUE ASSUMPTIONS'!K$46*'COST ASSUMPTIONS'!K$27,'COST ASSUMPTIONS'!K$44*'REVENUE ASSUMPTIONS'!K$70) -> 7291.2 | ... AA9: =CHOOSE($P$6,'COST ASSUMPTIONS'!AA$10*'REVENUE ASSUMPTIONS'!AA$22,'REVENUE ASSUMPTIONS'!AA$46*'COST ASSUMPTIONS'!AA$27,'COST ASSUMPTIONS'!AA$44*'REVENUE ASSUMPTIONS'!AA$70) -> 10894.4
B11: Gross Profit | C11: ₹ | D11: =D8-D9 -> 39600 | E11: =E8-E9 -> 42732.8 | F11: =F8-F9 -> 43665.6 | G11: =G8-G9 -> 44598.4 | H11: =H8-H9 -> 47942.4 | I11: =I8-I9 -> 48928 | J11: =J8-J9 -> 49913.6 | K11: =K8-K9 -> 53468.8 | ... AA11: =AA8-AA9 -> 191147.2
B12: Gross Profit Margin % | C12: % | D12: =D11/D8 -> 0.88 | E12: =E11/E8 -> 0.88 | F12: =F11/F8 -> 0.88 | G12: =G11/G8 -> 0.88 | H12: =H11/H8 -> 0.88 | I12: =I11/I8 -> 0.88 | J12: =J11/J8 -> 0.88 | K12: =K11/K8 -> 0.88 | ... AA12: =AA11/AA8 -> 0.94607843
B14: Variable Cost
B16: Marketing | C16: ₹ | D16: =CHOOSE($P$6,'COST ASSUMPTIONS'!D$12*'REVENUE ASSUMPTIONS'!D$10,'REVENUE ASSUMPTIONS'!D$34*'COST ASSUMPTIONS'!D$29,'COST ASSUMPTIONS'!D$46*'REVENUE ASSUMPTIONS'!D$58) -> 20000 | E16: =CHOOSE($P$6,'COST ASSUMPTIONS'!E$12*'REVENUE ASSUMPTIONS'!E$10,'REVENUE ASSUMPTIONS'!E$34*'COST ASSUMPTIONS'!E$29,'COST ASSUMPTIONS'!E$46*'REVENUE ASSUMPTIONS'!E$58) -> 20800 | F16: =CHOOSE($P$6,'COST ASSUMPTIONS'!F$12*'REVENUE ASSUMPTIONS'!F$10,'REVENUE ASSUMPTIONS'!F$34*'COST ASSUMPTIONS'!F$29,'COST ASSUMPTIONS'!F$46*'REVENUE ASSUMPTIONS'!F$58) -> 21600 | G16: =CHOOSE($P$6,'COST ASSUMPTIONS'!G$12*'REVENUE ASSUMPTIONS'!G$10,'REVENUE ASSUMPTIONS'!G$34*'COST ASSUMPTIONS'!G$29,'COST ASSUMPTIONS'!G$46*'REVENUE ASSUMPTIONS'!G$58) -> 22400 | H16: =CHOOSE($P$6,'COST ASSUMPTIONS'!H$12*'REVENUE ASSUMPTIONS'!H$10,'REVENUE ASSUMPTIONS'!H$34*'COST ASSUMPTIONS'!H$29,'COST ASSUMPTIONS'!H$46*'REVENUE ASSUMPTIONS'!H$58) -> 23200 | I16: =CHOOSE($P$6,'COST ASSUMPTIONS'!I$12*'REVENUE ASSUMPTIONS'!I$10,'REVENUE ASSUMPTIONS'!I$34*'COST ASSUMPTIONS'!I$29,'COST ASSUMPTIONS'!I$46*'REVENUE ASSUMPTIONS'!I$58) -> 24000 | J16: =CHOOSE($P$6,'COST ASSUMPTIONS'!J$12*'REVENUE ASSUMPTIONS'!J$10,'REVENUE ASSUMPTIONS'!J$34*'COST ASSUMPTIONS'!J$29,'COST ASSUMPTIONS'!J$46*'REVENUE ASSUMPTIONS'!J$58) -> 24800 | K16: =CHOOSE($P$6,'COST ASSUMPTIONS'!K$12*'REVENUE ASSUMPTIONS'!K$10,'REVENUE ASSUMPTIONS'!K$34*'COST ASSUMPTIONS'!K$29,'COST ASSUMPTIONS'!K$46*'REVENUE ASSUMPTIONS'!K$58) -> 25600 | ... AA16: =CHOOSE($P$6,'COST ASSUMPTIONS'!AA$12*'REVENUE ASSUMPTIONS'!AA$10,'REVENUE ASSUMPTIONS'!AA$34*'COST ASSUMPTIONS'!AA$29,'COST ASSUMPTIONS'!AA$46*'REVENUE ASSUMPTIONS'!AA$58) -> 28800
B17: Fulfillment | C17: ₹ | D17: =CHOOSE($P$6,'COST ASSUMPTIONS'!D$11*'REVENUE ASSUMPTIONS'!D$22,'REVENUE ASSUMPTIONS'!D$46*'COST ASSUMPTIONS'!D$28,'COST ASSUMPTIONS'!D$45*'REVENUE ASSUMPTIONS'!D$70) -> 2250 | E17: =CHOOSE($P$6,'COST ASSUMPTIONS'!E$11*'REVENUE ASSUMPTIONS'!E$22,'REVENUE ASSUMPTIONS'!E$46*'COST ASSUMPTIONS'!E$28,'COST ASSUMPTIONS'!E$45*'REVENUE ASSUMPTIONS'!E$70) -> 2428 | F17: =CHOOSE($P$6,'COST ASSUMPTIONS'!F$11*'REVENUE ASSUMPTIONS'!F$22,'REVENUE ASSUMPTIONS'!F$46*'COST ASSUMPTIONS'!F$28,'COST ASSUMPTIONS'!F$45*'REVENUE ASSUMPTIONS'!F$70) -> 2481 | G17: =CHOOSE($P$6,'COST ASSUMPTIONS'!G$11*'REVENUE ASSUMPTIONS'!G$22,'REVENUE ASSUMPTIONS'!G$46*'COST ASSUMPTIONS'!G$28,'COST ASSUMPTIONS'!G$45*'REVENUE ASSUMPTIONS'!G$70) -> 2534 | H17: =CHOOSE($P$6,'COST ASSUMPTIONS'!H$11*'REVENUE ASSUMPTIONS'!H$22,'REVENUE ASSUMPTIONS'!H$46*'COST ASSUMPTIONS'!H$28,'COST ASSUMPTIONS'!H$45*'REVENUE ASSUMPTIONS'!H$70) -> 2724 | I17: =CHOOSE($P$6,'COST ASSUMPTIONS'!I$11*'REVENUE ASSUMPTIONS'!I$22,'REVENUE ASSUMPTIONS'!I$46*'COST ASSUMPTIONS'!I$28,'COST ASSUMPTIONS'!I$45*'REVENUE ASSUMPTIONS'!I$70) -> 2780 | J17: =CHOOSE($P$6,'COST ASSUMPTIONS'!J$11*'REVENUE ASSUMPTIONS'!J$22,'REVENUE ASSUMPTIONS'!J$46*'COST ASSUMPTIONS'!J$28,'COST ASSUMPTIONS'!J$45*'REVENUE ASSUMPTIONS'!J$70) -> 2268.8 | K17: =CHOOSE($P$6,'COST ASSUMPTIONS'!K$11*'REVENUE ASSUMPTIONS'!K$22,'REVENUE ASSUMPTIONS'!K$46*'COST ASSUMPTIONS'!K$28,'COST ASSUMPTIONS'!K$45*'REVENUE ASSUMPTIONS'!K$70) -> 2430.4 | ... AA17: =CHOOSE($P$6,'COST ASSUMPTIONS'!AA$11*'REVENUE ASSUMPTIONS'!AA$22,'REVENUE ASSUMPTIONS'!AA$46*'COST ASSUMPTIONS'!AA$28,'COST ASSUMPTIONS'!AA$45*'REVENUE ASSUMPTIONS'!AA$70) -> 2971.2
B19: Total Variable Cost | C19: ₹ | D19: =D16+D17 -> 22250 | E19: =E16+E17 -> 23228 | F19: =F16+F17 -> 24081 | G19: =G16+G17 -> 24934 | H19: =H16+H17 -> 25924 | I19: =I16+I17 -> 26780 | J19: =J16+J17 -> 27068.8 | K19: =K16+K17 -> 28030.4 | ... AA19: =AA16+AA17 -> 31771.2
B21: Contribution Margin | C21: ₹ | D21: =D11-D19 -> 17350 | E21: =E11-E19 -> 19504.8 | F21: =F11-F19 -> 19584.6 | G21: =G11-G19 -> 19664.4 | H21: =H11-H19 -> 22018.4 | I21: =I11-I19 -> 22148 | J21: =J11-J19 -> 22844.8 | K21: =K11-K19 -> 25438.4 | ... AA21: =AA11-AA19 -> 159376
B22: Contribution Margin % | C22: % | D22: =D21/D8 -> 0.38555556 | E22: =E21/E8 -> 0.40166392 | F22: =F21/F8 -> 0.39469166 | G22: =G21/G8 -> 0.38801105 | H22: =H21/H8 -> 0.40415565 | I22: =I21/I8 -> 0.39834532 | J22: =J21/J8 -> 0.40276446 | K22: =K21/K8 -> 0.41867018 | ... AA22: =AA21/AA8 -> 0.78882765
B24: Fixed Cost
B26: General & Administrative | C26: ₹ | D26: =CHOOSE($P$6,'COST ASSUMPTIONS'!D16+'COST ASSUMPTIONS'!D17+'COST ASSUMPTIONS'!D18,'COST ASSUMPTIONS'!D33+'COST ASSUMPTIONS'!D34+'COST ASSUMPTIONS'!D35,'COST ASSUMPTIONS'!D50+'COST ASSUMPTIONS'!D51+'COST ASSUMPTIONS'!D52) -> 66000 | E26: =CHOOSE($P$6,'COST ASSUMPTIONS'!E16+'COST ASSUMPTIONS'!E17+'COST ASSUMPTIONS'!E18,'COST ASSUMPTIONS'!E33+'COST ASSUMPTIONS'!E34+'COST ASSUMPTIONS'!E35,'COST ASSUMPTIONS'!E50+'COST ASSUMPTIONS'!E51+'COST ASSUMPTIONS'!E52) -> 66000 | F26: =CHOOSE($P$6,'COST ASSUMPTIONS'!F16+'COST ASSUMPTIONS'!F17+'COST ASSUMPTIONS'!F18,'COST ASSUMPTIONS'!F33+'COST ASSUMPTIONS'!F34+'COST ASSUMPTIONS'!F35,'COST ASSUMPTIONS'!F50+'COST ASSUMPTIONS'!F51+'COST ASSUMPTIONS'!F52) -> 66000 | G26: =CHOOSE($P$6,'COST ASSUMPTIONS'!G16+'COST ASSUMPTIONS'!G17+'COST ASSUMPTIONS'!G18,'COST ASSUMPTIONS'!G33+'COST ASSUMPTIONS'!G34+'COST ASSUMPTIONS'!G35,'COST ASSUMPTIONS'!G50+'COST ASSUMPTIONS'!G51+'COST ASSUMPTIONS'!G52) -> 66000 | H26: =CHOOSE($P$6,'COST ASSUMPTIONS'!H16+'COST ASSUMPTIONS'!H17+'COST ASSUMPTIONS'!H18,'COST ASSUMPTIONS'!H33+'COST ASSUMPTIONS'!H34+'COST ASSUMPTIONS'!H35,'COST ASSUMPTIONS'!H50+'COST ASSUMPTIONS'!H51+'COST ASSUMPTIONS'!H52) -> 66000 | I26: =CHOOSE($P$6,'COST ASSUMPTIONS'!I16+'COST ASSUMPTIONS'!I17+'COST ASSUMPTIONS'!I18,'COST ASSUMPTIONS'!I33+'COST ASSUMPTIONS'!I34+'COST ASSUMPTIONS'!I35,'COST ASSUMPTIONS'!I50+'COST ASSUMPTIONS'!I51+'COST ASSUMPTIONS'!I52) -> 66000 | J26: =CHOOSE($P$6,'COST ASSUMPTIONS'!J16+'COST ASSUMPTIONS'!J17+'COST ASSUMPTIONS'!J18,'COST ASSUMPTIONS'!J33+'COST ASSUMPTIONS'!J34+'COST ASSUMPTIONS'!J35,'COST ASSUMPTIONS'!J50+'COST ASSUMPTIONS'!J51+'COST ASSUMPTIONS'!J52) -> 66000 | K26: =CHOOSE($P$6,'COST ASSUMPTIONS'!K16+'COST ASSUMPTIONS'!K17+'COST ASSUMPTIONS'!K18,'COST ASSUMPTIONS'!K33+'COST ASSUMPTIONS'!K34+'COST ASSUMPTIONS'!K35,'COST ASSUMPTIONS'!K50+'COST ASSUMPTIONS'!K51+'COST ASSUMPTIONS'!K52) -> 66000 | ... AA26: =CHOOSE($P$6,'COST ASSUMPTIONS'!AA16+'COST ASSUMPTIONS'!AA17+'COST ASSUMPTIONS'!AA18,'COST ASSUMPTIONS'!AA33+'COST ASSUMPTIONS'!AA34+'COST ASSUMPTIONS'!AA35,'COST ASSUMPTIONS'!AA50+'COST ASSUMPTIONS'!AA51+'COST ASSUMPTIONS'!AA52) -> 69000
B27: Other | C27: ₹ | D27: =CHOOSE($P$6,'COST ASSUMPTIONS'!D19,'COST ASSUMPTIONS'!D36,'COST ASSUMPTIONS'!D53) -> 2200 | E27: =CHOOSE($P$6,'COST ASSUMPTIONS'!E19,'COST ASSUMPTIONS'!E36,'COST ASSUMPTIONS'!E53) -> 2200 | F27: =CHOOSE($P$6,'COST ASSUMPTIONS'!F19,'COST ASSUMPTIONS'!F36,'COST ASSUMPTIONS'!F53) -> 2200 | G27: =CHOOSE($P$6,'COST ASSUMPTIONS'!G19,'COST ASSUMPTIONS'!G36,'COST ASSUMPTIONS'!G53) -> 2200 | H27: =CHOOSE($P$6,'COST ASSUMPTIONS'!H19,'COST ASSUMPTIONS'!H36,'COST ASSUMPTIONS'!H53) -> 2200 | I27: =CHOOSE($P$6,'COST ASSUMPTIONS'!I19,'COST ASSUMPTIONS'!I36,'COST ASSUMPTIONS'!I53) -> 2200 | J27: =CHOOSE($P$6,'COST ASSUMPTIONS'!J19,'COST ASSUMPTIONS'!J36,'COST ASSUMPTIONS'!J53) -> 2200 | K27: =CHOOSE($P$6,'COST ASSUMPTIONS'!K19,'COST ASSUMPTIONS'!K36,'COST ASSUMPTIONS'!K53) -> 2200 | ... AA27: =CHOOSE($P$6,'COST ASSUMPTIONS'!AA19,'COST ASSUMPTIONS'!AA36,'COST ASSUMPTIONS'!AA53) -> 2300
B29: Total Fixed Cost | C29: ₹ | D29: =D26+D27 -> 68200 | E29: =E26+E27 -> 68200 | F29: =F26+F27 -> 68200 | G29: =G26+G27 -> 68200 | H29: =H26+H27 -> 68200 | I29: =I26+I27 -> 68200 | J29: =J26+J27 -> 68200 | K29: =K26+K27 -> 68200 | ... AA29: =AA26+AA27 -> 71300
B31: Total Cost | C31: ₹ | D31: =D29+D19+D9 -> 95850 | E31: =E29+E19+E9 -> 97255.2 | F31: =F29+F19+F9 -> 98235.4 | G31: =G29+G19+G9 -> 99215.6 | H31: =H29+H19+H9 -> 100661.6 | I31: =I29+I19+I9 -> 101652 | J31: =J29+J19+J9 -> 102075.2 | K31: =K29+K19+K9 -> 103521.6 | ... AA31: =AA29+AA19+AA9 -> 113965.6
B33: EBT | C33: ₹ | D33: =D21-D29 -> -50850 | E33: =E21-E29 -> -48695.2 | F33: =F21-F29 -> -48615.4 | G33: =G21-G29 -> -48535.6 | H33: =H21-H29 -> -46181.6 | I33: =I21-I29 -> -46052 | J33: =J21-J29 -> -45355.2 | K33: =K21-K29 -> -42761.6 | ... AA33: =AA21-AA29 -> 88076
B35: Tax | C35: ₹ | D35: =IF(D$33>0,D$33*'COST ASSUMPTIONS'!$D$21,"N/A") -> N/A | E35: =IF(E$33>0,E$33*'COST ASSUMPTIONS'!$D$21,"N/A") -> N/A | F35: =IF(F$33>0,F$33*'COST ASSUMPTIONS'!$D$21,"N/A") -> N/A | G35: =IF(G$33>0,G$33*'COST ASSUMPTIONS'!$D$21,"N/A") -> N/A | H35: =IF(H$33>0,H$33*'COST ASSUMPTIONS'!$D$21,"N/A") -> N/A | I35: =IF(I$33>0,I$33*'COST ASSUMPTIONS'!$D$21,"N/A") -> N/A | J35: =IF(J$33>0,J$33*'COST ASSUMPTIONS'!$D$21,"N/A") -> N/A | K35: =IF(K$33>0,K$33*'COST ASSUMPTIONS'!$D$21,"N/A") -> N/A | ... AA35: =IF(AA$33>0,AA$33*'COST ASSUMPTIONS'!$D$21,"N/A") -> 22019
B37: Net Profit | C37: ₹ | D37: =IFERROR(D33-D35,D33) -> -50850 | E37: =IFERROR(E33-E35,E33) -> -48695.2 | F37: =IFERROR(F33-F35,F33) -> -48615.4 | G37: =IFERROR(G33-G35,G33) -> -48535.6 | H37: =IFERROR(H33-H35,H33) -> -46181.6 | I37: =IFERROR(I33-I35,I33) -> -46052 | J37: =IFERROR(J33-J35,J33) -> -45355.2 | K37: =IFERROR(K33-K35,K33) -> -42761.6 | ... AA37: =IFERROR(AA33-AA35,AA33) -> 66057
D39: Revenue Forecast
B42: =CHOOSE($P$6,NOTES!$C$2,NOTES!$C$19,NOTES!$C$36) -> In the base-case scenario, the startup’s revenue shows steady and moderate month-on-month growth over the forecast period. This growth reflects gradual customer acquisition, improving market awareness, and consistent sales performance. Revenue increases at a controlled pace, indicating stable demand and a realistic scaling strategy rather than aggressive expansion. Additionally, growth is supported by repeat customers and incremental improvements in pricing and distribution. Overall, the revenue trend represents a sustainable and achievable growth path
D60: Total Cost Forecast
B63: =CHOOSE($P$6,NOTES!$D$2,NOTES!$D$19,NOTES!$D$36) -> In the base-case scenario, total costs rise steadily as the business expands its operations. The increase is primarily driven by variable costs that move in line with revenue growth, such as production, marketing, and operational expenses. Fixed costs remain largely stable, showing effective budgeting and cost discipline. Furthermore, cost growth remains proportionate to revenue, preventing margin pressure. Overall, the cost structure reflects balanced growth with controlled spending under expected business conditions.
D81: Net Profit Forecast
B84: =CHOOSE($P$6,NOTES!$E$2,NOTES!$E$19,NOTES!$E$36) -> In the base-case scenario, net income remains negative during the initial periods as the startup continues to invest in growth and operations. As revenues improve and cost efficiency increases, the company reaches breakeven and transitions into positive net income. Profit growth thereafter is gradual, reflecting a cautious and realistic improvement in margins. Additionally, stable cost control supports consistent profitability in later periods. Overall, the net income trend indicates a financially viable business with sustainable long-term performance in the base-case scenario.
B102: Prepared for educational purpose
B104: This financial model has been created for a hypothetical startup with the objective of understanding how core financial statements are built and how assumptions drive overall business performance. The model is intentionally kept simple and focuses on three key components: revenue assumptions, cost assumptions, and the income statement. All figures used in the model are assumed purely for educational and learning purposes. Revenue assumptions are derived by estimating basic business drivers such as customer activity and pricing logic, allowing a structured view of how top-line growth could evolve over time. Cost assumptions are divided into variable and fixed costs to clearly understand the operational cost structure and its impact on profitability. These assumptions flow directly into the income statement, which highlights key metrics such as gross profit, operating profit, and net income. To assess uncertainty and risk, the model incorporates best-case, base-case, and worst-case scenarios. These scenarios help evaluate how changes in revenue and cost behavior can affect financial outcomes. However, for presentation clarity, only the base-case scenario is reflected in the final PDF, as it represents the most realistic and balanced outlook. Overall, this model demonstrates a foundational approach to financial modeling, emphasizes logical assumption-building, and provides a structured framework for analyzing startup-level financial performance.

Sheet NOTES
C1: Revenue Forecast | D1: Total Cast Forecast | E1: Net Profit Forecast
C2: In the best-case scenario, the startup’s revenue shows strong and consistent month-on-month growth throughout the forecast period. This growth reflects increasing customer adoption, successful market penetration, and effective pricing and sales strategies. The steady rise in revenue also indicates growing brand awareness, improved customer retention, and the ability of the business to scale operations efficiently without demand constraints. Additionally, revenue growth benefits from repeat customers and higher transaction volumes over time. | D2: In the best-case scenario, total costs increase gradually over the forecast period as the business scales its operations. The rise in costs is mainly driven by variable expenses such as production, logistics, and sales-related costs, which grow in line with revenue. Fixed costs remain relatively stable, reflecting disciplined financial planning and efficient resource allocation. Additionally, improved operational efficiency helps contain cost escalation despite higher activity levels. Overall, the cost trend indicates strong cost control and the presence of operating leverage | E2: In the best-case scenario, net income is negative during the initial periods as the startup incurs higher expenses related to setup, marketing, and expansion. As revenue grows and fixed costs are spread across a larger sales base, the company reaches breakeven and begins generating positive net income. Profitability improves steadily over time due to stronger margins and controlled cost growth. Additionally, increasing operating leverage amplifies earnings as revenues scale faster than expenses. Overall, the net income trend reflects a financially sustainable and scalable.
B9: Best
C19: In the base-case scenario, the startup’s revenue shows steady and moderate month-on-month growth over the forecast period. This growth reflects gradual customer acquisition, improving market awareness, and consistent sales performance. Revenue increases at a controlled pace, indicating stable demand and a realistic scaling strategy rather than aggressive expansion. Additionally, growth is supported by repeat customers and incremental improvements in pricing and distribution. Overall, the revenue trend represents a sustainable and achievable growth path | D19: In the base-case scenario, total costs rise steadily as the business expands its operations. The increase is primarily driven by variable costs that move in line with revenue growth, such as production, marketing, and operational expenses. Fixed costs remain largely stable, showing effective budgeting and cost discipline. Furthermore, cost growth remains proportionate to revenue, preventing margin pressure. Overall, the cost structure reflects balanced growth with controlled spending under expected business conditions. | E19: In the base-case scenario, net income remains negative during the initial periods as the startup continues to invest in growth and operations. As revenues improve and cost efficiency increases, the company reaches breakeven and transitions into positive net income. Profit growth thereafter is gradual, reflecting a cautious and realistic improvement in margins. Additionally, stable cost control supports consistent profitability in later periods. Overall, the net income trend indicates a financially viable business with sustainable long-term performance in the base-case scenario.
B26: Base
C36: In the worst-case scenario, the startup’s revenue grows slowly and remains volatile over the forecast period. This reflects weak customer acquisition, slower market penetration, and limited demand under unfavorable business conditions. Revenue growth is modest in the early and mid periods, indicating challenges in scaling and achieving consistent sales momentum. Additionally, lower repeat purchases and pricing pressure restrict overall revenue expansion. Overall, the revenue trend highlights constrained growth | D36: In the worst-case scenario, total costs remain relatively high and increase steadily despite slower revenue growth. A significant portion of costs is fixed in nature, limiting the company’s ability to reduce expenses in line with declining performance. Variable costs do not scale efficiently due to lower volumes, leading to weaker cost absorption. Furthermore, limited operating leverage results in sustained cost pressure on margins. Overall, the cost structure reflects operational rigidity and reduced flexibility under adverse conditions. | E36: In the worst-case scenario, net income remains negative throughout most of the forecast period as revenues are insufficient to cover total costs. Persistent losses are driven by high fixed expenses and weak margin expansion. Even as revenue improves slightly in later periods, profitability remains under pressure. Additionally, delayed breakeven and continued cash outflows increase financial risk. Overall, the net income trend indicates a stressed financial position and highlights the importance of cost restructuring and strategic intervention in adverse conditions.
B42: Worst
