Workbook

Sheet DATA SHEET
B1: PROFIT & LOSS
C2: 2014 | D2: =C2+1 -> 2015 | E2: =D2+1 -> 2016 | F2: =E2+1 -> 2017 | G2: =F2+1 -> 2018 | H2: =G2+1 -> 2019 | I2: =H2+1 -> 2020 | J2: =I2+1 -> 2021 | K2: =J2+1 -> 2022 | ... N2: =M2+1 -> 2025
B3: Sales - | C3: 43424 | D3: 46951 | E3: 51244 | F3: 55448 | G3: 54487 | H3: 59019 | I3: 61138 | J3: 61943 | K3: 79093 | L3: 90487 | M3: 89760 | N3: 89088
B4: Sales Growth % | C4: 0.1601 | D4: 0.0812 | E4: 0.0914 | F4: 0.082 | G4: -0.0173 | H4: 0.0832 | I4: 0.0359 | J4: 0.013 | K4: 0.2806 | L4: 0.1409 | M4: -0.008 | N4: -0.0075
B5: Expenses - | C5: 33788 | D5: 36652 | E5: 40448 | F5: 44128 | G5: 44100 | H5: 47406 | I5: 48795 | J5: =SUM(J6:J9) -> 50434 | K5: =SUM(K6:K9) -> 66236 | L5: =SUM(L6:L9) -> 77980 | M5: =SUM(M6:M9) -> 77646 | N5: =SUM(N6:N9) -> 75500
B6: Material Cost % - | C6: 0.07 | D6: 0.07 | E6: 0.06 | F6: 0.05 | G6: 0.03 | H6: 0.02 | I6: 0.02 | J6: 695 | K6: 673 | L6: 649 | M6: 383 | N6: 296
B7: Manufacturing Cost % | C7: 0.13 | D7: 0.12 | E7: 0 | F7: 0 | G7: 0 | H7: 0 | I7: 0 | J7: 8360 | K7: 10858 | L7: 11524 | M7: 10303 | N7: 10014
B8: Employee Cost % | C8: 0.48 | D8: 0.48 | E8: 0.48 | F8: 0.48 | G8: 0.5 | H8: 0.51 | I8: 0.53 | J8: 33237 | K8: 45007 | L8: 53764 | M8: 54930 | N8: 53347
B9: Other Cost % | C9: 0.11 | D9: 0.11 | E9: 0.25 | F9: 0.26 | G9: 0.28 | H9: 0.27 | I9: 0.25 | J9: 8142 | K9: 9698 | L9: 12043 | M9: 12030 | N9: 11843
B10: Operating Profit | C10: 9635 | D10: 10299 | E10: 10796 | F10: 11321 | G10: 10387 | H10: 11613 | I10: 12342 | J10: 14771 | K10: 16684 | L10: 16839 | M10: 16752 | N10: 18021
B11: OPM % | C11: 0.22 | D11: 0.22 | E11: 0.21 | F11: 0.2 | G11: 0.19 | H11: 0.2 | I11: 0.2 | J11: 0.24 | K11: 0.21 | L11: 0.19 | M11: 0.19 | N11: 0.2
B12: Other Income - | C12: 1922 | D12: 2450 | E12: 2752 | F12: 2623 | G12: 2550 | H12: 2614 | I12: 2728 | J12: 2404 | K12: 2067 | L12: 2275 | M12: 2631 | N12: 3909
B13: Exceptional items | C13: 154 | D13: 395 | E13: 265 | F13: 0 | G13: 0 | H13: 0 | I13: 0 | J13: 0 | K13: 0 | L13: 9 | M13: 207 | N13: 61
B14: Other income normal | C14: 1767 | D14: 2055 | E14: 2488 | F14: 2623 | G14: 2550 | H14: 2614 | I14: 2728 | J14: 2404 | K14: 2067 | L14: 2266 | M14: 2424 | N14: 3849
B15: Interest | C15: 383 | D15: 350 | E15: 558 | F15: 594 | G15: 583 | H15: 738 | I15: 733 | J15: 509 | K15: 532 | L15: 1008 | M15: 1255 | N15: 1477
B16: Depreciation | C16: 1060 | D16: 1175 | E16: 1496 | F16: 2310 | G16: 2112 | H16: 1947 | I16: 2086 | J16: 2763 | K16: 3078 | L16: 3340 | M16: 3407 | N16: 2958
B17: Profit before tax | C17: 10114 | D17: 11224 | E17: 11494 | F17: 11039 | G17: 10242 | H17: 11542 | I17: 12252 | J17: 13903 | K17: 15141 | L17: 14766 | M17: 14721 | N17: 17496
... B27: Dividend Payout % | C27: 0.25 | D27: 0.34 | E27: 0.17 | F27: 0.06 | G27: 0.06 | H27: 0.07 | I27: 0.06 | J27: 0.05 | K27: 0.27 | L27: 0.05 | M27: 0.05 | N27: 0.48
B31: BALANCE SHEET
C32: 2014 | D32: =C32+1 -> 2015 | E32: =D32+1 -> 2016 | F32: =E32+1 -> 2017 | G32: =F32+1 -> 2018 | H32: =G32+1 -> 2019 | I32: =H32+1 -> 2020 | J32: =I32+1 -> 2021 | K32: =J32+1 -> 2022 | ... N32: =M32+1 -> 2025
B33: Equity Capital | C33: 493 | D33: 494 | E33: 494 | F33: 486 | G33: 905 | H33: 1207 | I33: 1143 | J33: 1096 | K33: 1096 | L33: 1098 | M33: 1045 | N33: 2094
B34: Reserves | C34: 31636 | D34: 36598 | E34: 45651 | F34: 51184 | G34: 47022 | H34: 55216 | I34: 54179 | J34: 53805 | K34: 64307 | L34: 76570 | M34: 73943 | N34: 80736
B35: Borrowings - | C35: 5159 | D35: 7891 | E35: 12522 | F35: 14241 | G35: 13901 | H35: 9947 | I35: 9724 | J35: 10451 | K35: 17593 | L35: 17467 | M35: 16465 | N35: 19204
B36: Long term Borrowings | C36: 1091 | D36: 1271 | E36: 1736 | F36: 1961 | G36: 4527 | H36: 2837 | I36: 484 | J36: 746 | K36: 5646 | L36: 6127 | M36: 6230 | N36: 6395
B37: Short term Borrowings | C37: 3943 | D37: 6444 | E37: 10265 | F37: 11674 | G37: 7960 | H37: 6808 | I37: 5402 | J37: 6036 | K37: 9523 | L37: 8882 | M37: 7917 | N37: 9786
B38: Lease Liabilities | C38: 0 | D38: 0 | E38: 0 | F38: 0 | G38: 0 | H38: 0 | I38: 1920 | J38: 2118 | K38: 2423 | L38: 2457 | M38: 2318 | N38: 3022
B39: Other Borrowings | C39: 125 | D39: 176 | E39: 521 | F39: 606 | G39: 1415 | H39: 301 | I39: 1918 | J39: 1551 | K39: 0 | L39: 0 | M39: 0 | N39: 0
B40: Other Liabilities - | C40: 12245 | D40: 13367 | E40: 12924 | F40: 12761 | G40: 13563 | H40: 16217 | I40: 15954 | J40: 17213 | K40: 24280 | L40: 21789 | M40: 23611 | N40: 26362
B41: Non Controlling Interest | C41: 139 | D41: 165 | E41: 221 | F41: 239 | G41: 241 | H41: 264 | I41: 188 | J41: 150 | K41: 53 | L41: 60 | M41: 133 | N41: 214
B42: Trade Payables | C42: 5216 | D42: 5849 | E42: 4902 | F42: 4867 | G42: 5120 | H42: 6266 | I42: 5840 | J42: 5417 | K42: 6252 | L42: 5972 | M42: 8857 | N42: 8825
B43: Advance from Customers | C43: 328 | D43: 220 | E43: 238 | F43: 239 | G43: 190 | H43: 136 | I43: 146 | J43: 36 | K43: 63 | L43: 64 | M43: 119 | N43: 79
B44: Other liability items | C44: 6562 | D44: 7134 | E44: 7562 | F44: 7415 | G44: 8012 | H44: 9551 | I44: 9780 | J44: 11610 | K44: 17913 | L44: 15694 | M44: 14501 | N44: 17244
... B66: Total Assets | C66: 49533 | D66: 58350 | E66: 71590 | F66: 78672 | G66: 75391 | H66: 82586 | I66: 81000 | J66: 82566 | K66: 107276 | L66: 116924 | M66: 115064 | N66: 128396
H68: =SUM(J47,J48,J49,J50,J51,J52,J53,J54,J55,J58,J59) -> 56995
B70: CASH FLOW STATEMENT
C71: 2014 | D71: =C71+1 -> 2015 | E71: =D71+1 -> 2016 | F71: =E71+1 -> 2017 | G71: =F71+1 -> 2018 | H71: =G71+1 -> 2019 | I71: =H71+1 -> 2020 | J71: =I71+1 -> 2021 | K71: =J71+1 -> 2022 | ... N71: =M71+1 -> 2025
B72: Cash from Operating Activity - | C72: 6790 | D72: 7840 | E72: 7887 | F72: 9277 | G72: 8423 | H72: 11632 | I72: 10064 | J72: 14755 | K72: 11080 | L72: 13060 | M72: 17622 | N72: 16943
B73: Profit from Operations | C73: 9977 | D73: 10990 | E73: 11180 | F73: 11374 | G73: 11322 | H73: 11430 | I73: 13088 | J73: 14954 | K73: 17297 | L73: 17538 | M73: 17416 | N73: 18533
B74: Receivables | C74: -1566 | D74: -888 | E74: -532 | F74: 335 | G74: -974 | H74: 139 | I74: -333 | J74: 1285 | K74: -4323 | L74: -98 | M74: 782 | N74: 189
B75: Inventory | C75: 97 | D75: -256 | E75: -54 | F75: 148 | G75: 54 | H75: -57 | I75: 208 | J75: 80 | K75: -26 | L75: 16 | M75: 29 | N75: 21
...

Sheet STATEMENTS
B3: BALANCE SHEET
B5: Item | C5: FY21 | D5: FY22 | E5: FY23 | F5: FY24 | G5: FY25
B6: ASSETS
B7: Property, Plant & Equipment | C7: 6575 | D7: 7461 | E7: 8234 | F7: 7413 | G7: 7847
B8: Right-of-use Assets | C8: 1642 | D8: 1887 | E8: 1870 | F8: 1796 | G8: 2560
B9: Capital Work-in-progress | C9: 1853 | D9: 1602 | E9: 617 | F9: 723 | G9: 196
B10: Goodwill | C10: 13515 | D10: 24286 | E10: 30349 | F10: 31145 | G10: 32035
B11: Other Intangible Assets | C11: 1309 | D11: 4356 | E11: 4305 | F11: 3275 | G11: 2745
B12: Investments (Non-current) | C12: 1058 | D12: 1911 | E12: 2072 | F12: 2163 | G12: 2646
B13: Trade Receivables (Non-current) | C13: 436 | D13: 476 | E13: 86 | F13: 405 | G13: 30
B14: Other Financial Assets (Non-current) | C14: 609 | D14: 608 | E14: 633 | F14: 555 | G14: 466
B15: Deferred Tax Assets | C15: 166 | D15: 230 | E15: 210 | F15: 182 | G15: 256
B16: Non-current Tax Assets | C16: 1432 | D16: 1026 | E16: 1192 | F16: 904 | G16: 723
B17: Other Non-current Assets | C17: 1671 | D17: 1510 | E17: 1376 | F17: 1058 | G17: 771
B18: Total Non-current Assets | C18: 30414 | D18: 45430 | E18: 51024 | F18: 49724 | G18: 50408
... B29: Total Current Assets | C29: 52319 | D29: 62075 | E29: 66109 | F29: 65063 | G29: 77777
B30: TOTAL ASSETS | C30: 82732 | D30: 1,07,505 | E30: 1,17,133 | F30: 1,14,791 | G30: 1,28,185
B31: EQUITY & LIABILITIES
B32: Share Capital | C32: 1096 | D32: 1096 | E32: 1098 | F32: 1045 | G32: 2094
B33: Other Equity | C33: 53805 | D33: 64307 | E33: 76570 | F33: 73488 | G33: 80270
B34: Equity Attributable | C34: 54901 | D34: 65403 | E34: 77667 | F34: 74533 | G34: 82364
B35: Non-controlling Interest | C35: 150 | D35: 52 | E35: 59 | F35: 134 | G35: 214
B36: TOTAL EQUITY | C36: 55051 | D36: 65455 | E36: 77726 | F36: 74667 | G36: 82578
B37: Borrowings (Non-current) | C37: 746 | D37: 5646 | E37: 6127 | F37: 6230 | G37: 6395
B38: Lease Liabilities (Non-current) | C38: 1351 | D38: 1518 | E38: 1595 | F38: 1396 | G38: 2219
B39: Other Financial Liabilities | C39: 229 | D39: 296 | E39: 265 | F39: 499 | G39: 779
B40: Provisions (Non-current) | C40: 306 | D40: 272 | E40: 295 | F40: 422 | G40: 466
B41: Deferred Tax Liabilities | C41: 461 | D41: 1214 | E41: 1515 | F41: 1747 | G41: 1644
B42: Tax Liabilities (Non-current) | C42: 1107 | D42: 1782 | E42: 2178 | F42: 3709 | G42: 4202
B43: Other Non-current Liabilities | C43: 478 | D43: 485 | E43: 639 | F43: 875 | G43: 1276
... B55: TOTAL LIABILITIES | C55: 27681 | D55: 42050 | E55: 39406 | F55: 40124 | G55: 45607
B56: TOTAL EQUITY + LIABILITIES | C56: 82732 | D56: 1,07,505 | E56: 1,17,133 | F56: 1,14,791 | G56: 1,28,185
B59: PROFIT AND LOSS
B61: Item | C61: FY21 | D61: FY22 | E61: FY23 | F61: FY24 | G61: FY25
B62: INCOME
B63: Revenue from operations | C63: 62243 | D63: 79529 | E63: 90935 | F63: 89794 | G63: 89088
B64: Other income | C64: 2382 | D64: 2061 | E64: 2266 | F64: 2631 | G64: 3884
B65: Total income | C65: =SUM(C63:C64) -> 64625 | D65: =SUM(D63:D64) -> 81590 | E65: =SUM(E63:E64) -> 93201 | F65: =SUM(F63:F64) -> 92425 | G65: =SUM(G63:G64) -> 92972
B66: EXPENSES
B67: Purchases of stock-in-trade | C67: 695 | D67: 674 | E67: 649 | F67: 383 | G67: 297
...

Sheet ABOUT
B1: WIPRO | C1: ABOUT WIPRO
C5: Wipro is a leading global information technology, consulting, and business process services company headquartered in Bengaluru, India. Founded in 1945, the company has transformed from a consumer products business into one of the world’s major IT service providers. Wipro delivers innovative solutions in cloud computing, cybersecurity, artificial intelligence, digital transformation, analytics, engineering services, and consulting. The company serves clients across industries including banking, healthcare, retail, manufacturing, telecommunications, and energy. With operations in more than 60 countries and a strong global workforce, Wipro focuses on helping businesses improve efficiency, accelerate digital growth, and enhance customer experiences through technology-driven solutions. The company is recognized for its commitment to sustainability, ethical business practices, innovation, and long-term value creation for stakeholders.
B15: KEY FINANCIAL METRICS | C15: 44276 | D15: =EDATE(C15,12) -> 44641 | E15: =EDATE(D15,12) -> 45006 | F15: =EDATE(E15,12) -> 45372 | G15: =EDATE(F15,12) -> 45737 | J15: SHARE PRICE 2 YEARS
B18: Total Revenue | C18: ='PROFIT & LOSS'!D10 -> 64625 | D18: ='PROFIT & LOSS'!E10 -> 81590 | E18: ='PROFIT & LOSS'!F10 -> 93201 | F18: ='PROFIT & LOSS'!G10 -> 92425 | G18: ='PROFIT & LOSS'!H10 -> 92972
B19: Rev Growth % | C19: ='COMMON SIZE STATEMENT'!K9 -> N/A | D19: ='COMMON SIZE STATEMENT'!L9 -> 0.27771798 | E19: ='COMMON SIZE STATEMENT'!M9 -> 0.14341938 | F19: ='COMMON SIZE STATEMENT'!N9 -> -0.012547424 | G19: ='COMMON SIZE STATEMENT'!O9 -> -0.0078624407
B20: Gross Profit Margins % | C20: ='COMMON SIZE STATEMENT'!D12 -> 0.32572337 | D20: ='COMMON SIZE STATEMENT'!E12 -> 0.283142 | E20: ='COMMON SIZE STATEMENT'!F12 -> 0.28480783 | F20: ='COMMON SIZE STATEMENT'!G12 -> 0.28203443 | G20: ='COMMON SIZE STATEMENT'!H12 -> 0.31076015
B21: EBIT Margins % | C21: ='COMMON SIZE STATEMENT'!D16 -> 0.22745068 | D21: ='COMMON SIZE STATEMENT'!E16 -> 0.17791396 | E21: ='COMMON SIZE STATEMENT'!F16 -> 0.17467624 | F21: ='COMMON SIZE STATEMENT'!G16 -> 0.17345956 | G21: ='COMMON SIZE STATEMENT'!H16 -> 0.20378178
B22: Net Profit Margins % | C22: ='COMMON SIZE STATEMENT'!D20 -> 0.17261122 | D22: ='COMMON SIZE STATEMENT'!E20 -> 0.13584998 | E22: ='COMMON SIZE STATEMENT'!F20 -> 0.126651 | F22: ='COMMON SIZE STATEMENT'!G20 -> 0.12083311 | G22: ='COMMON SIZE STATEMENT'!H20 -> 0.14188143
B23: EPS | C23: ='PROFIT & LOSS'!D42 -> 19.07 | D23: ='PROFIT & LOSS'!E42 -> 22.31 | E23: ='PROFIT & LOSS'!F42 -> 20.68 | F23: ='PROFIT & LOSS'!G42 -> 10.41 | G23: ='PROFIT & LOSS'!H42 -> 12.52
B24: EPS Growth % | C24: N/A | D24: ='PROFIT & LOSS'!E42/'PROFIT & LOSS'!D42-1 -> 0.16990037 | E24: ='PROFIT & LOSS'!F42/'PROFIT & LOSS'!E42-1 -> -0.073061407 | F24: ='PROFIT & LOSS'!G42/'PROFIT & LOSS'!F42-1 -> -0.49661509 | G24: ='PROFIT & LOSS'!H42/'PROFIT & LOSS'!G42-1 -> 0.20268972
B25: DPS | C25: ='PROFIT & LOSS'!D44/'PROFIT & LOSS'!D41 -> 0.5205503 | D25: ='PROFIT & LOSS'!E44/'PROFIT & LOSS'!E41 -> 0.51548335 | E25: ='PROFIT & LOSS'!F44/'PROFIT & LOSS'!F41 -> 5.9774094 | F25: ='PROFIT & LOSS'!G44/'PROFIT & LOSS'!G41 -> 0.95218985 | G25: ='PROFIT & LOSS'!H44/'PROFIT & LOSS'!H41 -> 11.083244
B26: DPS Growth % | C26: N/A | D26: =D25/C25-1 -> -0.0097338297 | E26: =E25/D25-1 -> 10.595737 | F26: =F25/E25-1 -> -0.84070192 | G26: =G25/F25-1 -> 10.639741
B29: KEY FINANCIAL RATIOS | C29: 44276 | D29: =EDATE(C29,12) -> 44641 | E29: =EDATE(D29,12) -> 45006 | F29: =EDATE(E29,12) -> 45372 | G29: =EDATE(F29,12) -> 45737 | J29: SHAREHOLDING PATTERN
B32: P/E | C32: ='RATIO ANALYSIS'!C46 -> 10.015732 | D32: ='RATIO ANALYSIS'!D46 -> 13.265352 | E32: ='RATIO ANALYSIS'!E46 -> 8.8646035 | F32: ='RATIO ANALYSIS'!F46 -> 23.29683 | G32: ='RATIO ANALYSIS'!G46 -> 19.672524
B33: EV/EBITDA | C33: ='RATIO ANALYSIS'!C47 -> 10.949375 | D33: ='RATIO ANALYSIS'!D47 -> 18.143196 | E33: ='RATIO ANALYSIS'!E47 -> 5.4223419 | F33: ='RATIO ANALYSIS'!F47 -> 7.0629605 | G33: ='RATIO ANALYSIS'!G47 -> 6.5408451
B34: Debt to Equity | C34: ='BALANCE SHEET'!D69/'BALANCE SHEET'!D77 -> 0.50284282 | D34: ='BALANCE SHEET'!E69/'BALANCE SHEET'!E77 -> 0.63541364 | E34: ='BALANCE SHEET'!F69/'BALANCE SHEET'!F77 -> 0.50672225 | F34: ='BALANCE SHEET'!G69/'BALANCE SHEET'!G77 -> 0.53738599 | G34: ='BALANCE SHEET'!H69/'BALANCE SHEET'!H77 -> 0.55227785
B35: ROE | C35: ='DUPONT ANALYSIS'!D12 -> N/A | D35: ='DUPONT ANALYSIS'!E12 -> 0.18395765 | E35: ='DUPONT ANALYSIS'!F12 -> 0.16488106 | F35: ='DUPONT ANALYSIS'!G12 -> 0.14656745 | G35: ='DUPONT ANALYSIS'!H12 -> 0.1677764
B36: ROIC | C36: ='INTRINSIC GROWTH'!D64 -> 0.31677514 | D36: ='INTRINSIC GROWTH'!E64 -> 0.23163337 | E36: ='INTRINSIC GROWTH'!F64 -> 0.21503104 | F36: ='INTRINSIC GROWTH'!G64 -> 0.21317448 | G36: ='INTRINSIC GROWTH'!H64 -> 0.22320135
B37: ROA | C37: ='RATIO ANALYSIS'!C21 -> N/A | D37: ='RATIO ANALYSIS'!D21 -> 0.11680955 | E37: ='RATIO ANALYSIS'!E21 -> 0.1053181 | F37: ='RATIO ANALYSIS'!F21 -> 0.096315302 | G37: ='RATIO ANALYSIS'!G21 -> 0.10857863
B40: TOP SHAREHOLDERS | C40: NO. of S. | D40: HOLD | E40: REPRESENTATION | J40: INDEXED NIFTY & WIPRO
B43: ='DATA SHEET'!B356 -> Mr. Azim Hasham Premji (Zash Traders) | C43: ='DATA SHEET'!C356 -> 220.21 Cr | D43: ='DATA SHEET'!D356 -> 0.2103
B44: ='DATA SHEET'!B357 -> Mr. Azim Hasham Premji (Prazim Traders) | C44: ='DATA SHEET'!C357 -> 216.03 Cr | D44: ='DATA SHEET'!D357 -> 0.206
B45: ='DATA SHEET'!B358 -> Mr. Azim Hasham Premji (Hasham Traders) | C45: ='DATA SHEET'!C358 -> 188.68 Cr | D45: ='DATA SHEET'!D358 -> 0.1799
B46: ='DATA SHEET'!B359 -> Azim Premji Trust | C46: ='DATA SHEET'!C359 -> 68.04 Cr | D46: ='DATA SHEET'!D359 -> 0.0649
B47: ='DATA SHEET'!B360 -> Azim H. Premji | C47: ='DATA SHEET'!C360 -> 43.12 Cr | D47: ='DATA SHEET'!D360 -> 0.0411
B48: ='DATA SHEET'!B361 -> LIC ULIP Growth Fund | C48: ='DATA SHEET'!C361 -> 28.02 Cr | D48: ='DATA SHEET'!D361 -> 0.0267
B49: ='DATA SHEET'!B362 -> JP Morgan Chase Bank | C49: ='DATA SHEET'!C362 -> 25.97 Cr | D49: ='DATA SHEET'!D362 -> 0.0248
B50: ='DATA SHEET'!B363 -> Prazim Trading & Investment Co. Pvt Ltd | C50: ='DATA SHEET'!C363 -> 19.37 Cr | D50: ='DATA SHEET'!D363 -> 0.0185
B51: ='DATA SHEET'!B364 -> ICICI Prudential Children’s Fund | C51: ='DATA SHEET'!C364 -> 16.15 Cr | D51: ='DATA SHEET'!D364 -> 0.0154
B54: MANAGERIAL REMUNERATION | C54: DESIGN. | D54: REMUN. | E54: EXP. | F54: X of MEDIAN SALARY | J54: CAPITAL STRUCTURE
B57: Srinivas Pallia | C57: CEO | D57: 53.64 Cr. | E57: 30 + Years | F57: 548x | J57: Current Price | L57: ='PV OF FCFF'!$C$45 -> 246.3
B58: Rishad Premji | C58: Ex. Chairman | D58: 13.7 Cr. | E58: 20 + Years | F58: 140x | J58: N. of Shares (Cr.) | L58: ='PROFIT & LOSS'!$H$41 -> 566.17
B59: Aparna C. Iyer | C59: CFO | D59: 6.4 Cr. | E59: 20 + Years | F59: 65x | J59: Market Cap (Cr.) | L59: =L57*L58 -> 139447.67
B62: AMBITIONS REALIZED | J62: Less: Cash | L62: ='BALANCE SHEET'!H15 -> 12358
J63: Add: Debt | L63: ='BALANCE SHEET'!H45+'BALANCE SHEET'!H59 -> 16181
J64: Less: Min. Int | L64: ='BALANCE SHEET'!H75 -> 214
J65: Enterprise Value | L65: =L59+L63-L62-L64 -> 143056.67

Sheet P & L ASSUMPTIONS
B1: WIPRO | D1: INCOME STATEMENT ASSUMPTION | K1: INCOME STATEMENT - FORECAST (BEST CASE) | R1: INCOME STATEMENT - FORECAST (BASE CASE) | Y1: INCOME STATEMENT - FORECAST (WORST CASE)
C3: UNIT | D3: Year 1 | E3: Year 2 | F3: Year 3 | G3: Year 4 | H3: Year 5 | K3: Year 6 | L3: Year 7 | M3: Year 8 | N3: Year 9 | O3: Year 10 | R3: Year 6 | S3: Year 7 | T3: Year 8 | U3: Year 9 | V3: Year 10 | Y3: Year 6 | Z3: Year 7 | AA3: Year 8 | AB3: Year 9 | AC3: Year 10
B4: Particulars | D4: ='PROFIT & LOSS'!D4 -> 44276 | E4: ='PROFIT & LOSS'!E4 -> 44641 | F4: ='PROFIT & LOSS'!F4 -> 45006 | G4: ='PROFIT & LOSS'!G4 -> 45372 | H4: ='PROFIT & LOSS'!H4 -> 45737 | K4: ='PROFIT & LOSS'!K4 -> 46102 | L4: ='PROFIT & LOSS'!L4 -> 46467 | M4: ='PROFIT & LOSS'!M4 -> 46833 | N4: ='PROFIT & LOSS'!N4 -> 47198 | O4: ='PROFIT & LOSS'!O4 -> 47563 | R4: =K$4 -> 46102 | S4: =L$4 -> 46467 | T4: =M$4 -> 46833 | U4: =N$4 -> 47198 | V4: =O$4 -> 47563 | Y4: =R$4 -> 46102 | Z4: =S$4 -> 46467 | AA4: =T$4 -> 46833 | AB4: =U$4 -> 47198 | AC4: =V$4 -> 47563
B6: Total Income | C6: ₹ | D6: ='PROFIT & LOSS'!D10 -> 64625 | E6: ='PROFIT & LOSS'!E10 -> 81590 | F6: ='PROFIT & LOSS'!F10 -> 93201 | G6: ='PROFIT & LOSS'!G10 -> 92425 | H6: ='PROFIT & LOSS'!H10 -> 92972 | K6: =K11+K18+K28 -> 94095.92 | L6: =L11+L18+L28 -> 95242.731 | M6: =M11+M18+M28 -> 97322.148 | N6: =N11+N18+N28 -> 99453.628 | O6: =O11+O18+O28 -> 102584.34 | R6: =R11+R18+R28 -> 92275.32 | S6: =S11+S18+S28 -> 91597.259 | T6: =T11+T18+T28 -> 92684.516 | U6: =U11+U18+U28 -> 93791.21 | V6: =V11+V18+V28 -> 95808.665 | Y6: =Y11+Y18+Y28 -> 91791.04 | Z6: =Z11+Z18+Z28 -> 90636.339 | AA6: =AA11+AA18+AA28 -> 89940.023 | AB6: =AB11+AB18+AB28 -> 89259.071 | AC6: =AC11+AC18+AC28 -> 90287.974
B8: IT SERVICES | K8: IT SERVICES - FORECAST (BEST CASE) | R8: IT SERVICES - FORECAST (BASE CASE) | Y8: IT SERVICES - FORECAST (WORST CASE)
B11: Revenue from IT Services | C11: ₹ | D11: 61830 | E11: 79529 | F11: 90935 | G11: 89382 | H11: 89088 | K11: =K$22*K$13 -> 89708.943 | L11: =L$22*L$13 -> 90606.033 | M11: =M$22*M$13 -> 92418.153 | N11: =N$22*N$13 -> 94266.517 | O11: =O$22*O$13 -> 97094.512 | R11: =R$22*R$13 -> 88020.726 | S11: =S$22*S$13 -> 87140.519 | T11: =T$22*T$13 -> 88011.924 | U11: =U$22*U$13 -> 88892.043 | V11: =V$22*V$13 -> 90669.884 | Y11: =Y$22*Y$13 -> 87663.928 | Z11: =Z$22*Z$13 -> 86348.969 | AA11: =AA$22*AA$13 -> 85485.48 | AB11: =AB$22*AB$13 -> 84630.625 | AC11: =AC$22*AC$13 -> 85476.931
B12: YoY Change | C12: % | D12: N/A | E12: =E11/D11-1 -> 0.28625263 | F12: =F11/E11-1 -> 0.14341938 | G12: =G11/F11-1 -> -0.017078133 | H12: =H11/G11-1 -> -0.0032892529 | K12: =$K$11/$H$11-1 -> 0.00697 | L12: =L11/K11-1 -> 0.01 | M12: =M11/L11-1 -> 0.02 | N12: =N11/M11-1 -> 0.02 | O12: =O11/N11-1 -> 0.03 | R12: =$R$11/$H$11-1 -> -0.01198 | S12: =S11/R11-1 -> -0.01 | T12: =T11/S11-1 -> 0.01 | U12: =U11/T11-1 -> 0.01 | V12: =V11/U11-1 -> 0.02 | Y12: =$Y$11/$H$11-1 -> -0.015985 | Z12: =Z11/Y11-1 -> -0.015 | AA12: =AA11/Z11-1 -> -0.01 | AB12: =AB11/AA11-1 -> -0.01 | AC12: =AC11/AB11-1 -> 0.01
B13: % of Rev | C13: % | D13: =D11/D22 -> 0.99336472 | E13: =E11/E22 -> 1 | F13: =F11/F22 -> 1 | G13: =G11/G22 -> 0.99541172 | H13: =H11/H22 -> 1 | K13: =D$43 -> 0.997 | L13: =E$43 -> 0.997 | M13: =F$43 -> 0.997 | N13: =G$43 -> 0.997 | O13: =H$43 -> 0.997 | R13: =D$44 -> 0.998 | S13: =E$44 -> 0.998 | T13: =F$44 -> 0.998 | U13: =G$44 -> 0.998 | V13: =H$44 -> 0.998 | Y13: =D$45 -> 0.999 | Z13: =E$45 -> 0.999 | AA13: =F$45 -> 0.999 | AB13: =G$45 -> 0.999 | AC13: =H$45 -> 0.999
B15: IT PRODUCTS | K15: IT PRODUCTS - FORECAST (BEST CASE) | R15: IT PRODUCTS - FORECAST (BASE CASE) | Y15: IT PRODUCTS - FORECAST (WORST CASE)
B18: Revenue from IT Products | C18: ₹ | D18: =D6-(D11+D28) -> 413 | E18: =E6-(E11+E28) -> 0 | F18: =F6-(F11+F28) -> 0 | G18: =G6-(G11+G28) -> 412 | H18: =H6-(H11+H28) -> 0 | K18: =K$22*K$20 -> 269.93664 | L18: =L$22*L$20 -> 272.63601 | M18: =M$22*M$20 -> 278.08873 | N18: =N$22*N$20 -> 283.6505 | O18: =O$22*O$20 -> 292.16002 | R18: =R$22*R$20 -> 176.39424 | S18: =S$22*S$20 -> 174.6303 | T18: =T$22*T$20 -> 176.3766 | U18: =U$22*U$20 -> 178.14037 | V18: =V$22*V$20 -> 181.70317 | Y18: =Y22*Y20 -> 87.75168 | Z18: =Z22*Z20 -> 86.435405 | AA18: =AA22*AA20 -> 85.571051 | AB18: =AB22*AB20 -> 84.71534 | AC18: =AC22*AC20 -> 85.562494
B19: YoY Change | C19: % | D19: =D12 -> N/A | E19: =E18/D18-1 -> -1 | F19: N/A | G19: N/A | H19: =H18/G18-1 -> -1 | K19: N/A | L19: =L$18/K$18-1 -> 0.01 | M19: =M$18/L$18-1 -> 0.02 | N19: =N$18/M$18-1 -> 0.02 | O19: =O$18/N$18-1 -> 0.03 | R19: N/A | S19: =S$18/R$18-1 -> -0.01 | T19: =T$18/S$18-1 -> 0.01 | U19: =U$18/T$18-1 -> 0.01 | V19: =V$18/U$18-1 -> 0.02 | Y19: N/A | Z19: =Z18/Y18-1 -> -0.015 | AA19: =AA18/Z18-1 -> -0.01 | AB19: =AB18/AA18-1 -> -0.01 | AC19: =AC18/AB18-1 -> 0.01
B20: % of Rev | C20: % | D20: =D18/D22 -> 0.0066352843 | E20: =E18/E22 -> 0 | F20: =F18/F22 -> 0 | G20: =G18/G22 -> 0.0045882798 | H20: =H18/H22 -> 0 | K20: =100%-K13 -> 0.003 | L20: =100%-L13 -> 0.003 | M20: =100%-M13 -> 0.003 | N20: =100%-N13 -> 0.003 | O20: =100%-O13 -> 0.003 | R20: =100%-R13 -> 0.002 | S20: =100%-S13 -> 0.002 | T20: =100%-T13 -> 0.002 | U20: =100%-U13 -> 0.002 | V20: =100%-V13 -> 0.002 | Y20: =100%-Y13 -> 0.001 | Z20: =100%-Z13 -> 0.001 | AA20: =100%-AA13 -> 0.001 | AB20: =100%-AB13 -> 0.001 | AC20: =100%-AC13 -> 0.001
B22: Rev from Operations | C22: ₹ | D22: =D11+D18 -> 62243 | E22: =E11+E18 -> 79529 | F22: =F11+F18 -> 90935 | G22: =G11+G18 -> 89794 | H22: =H11+H18 -> 89088 | K22: =$H$22+($H$22*$D$37) -> 89978.88 | L22: =K$22+(K$22*E$37) -> 90878.669 | M22: =L$22+(L$22*F$37) -> 92696.242 | N22: =M$22+(M$22*G$37) -> 94550.167 | O22: =N$22+(N$22*H$37) -> 97386.672 | R22: =$H$22+($H$22*$D$38) -> 88197.12 | S22: =R$22+(R$22*E$38) -> 87315.149 | T22: =S$22+(S$22*F$38) -> 88188.3 | U22: =T$22+(T$22*G$38) -> 89070.183 | V22: =U$22+(U$22*H$38) -> 90851.587 | Y22: =$H$22+($H$22*$D$39) -> 87751.68 | Z22: =Y$22+(Y$22*E$39) -> 86435.405 | AA22: =Z$22+(Z$22*F$39) -> 85571.051 | AB22: =AA$22+(AA$22*G$39) -> 84715.34 | AC22: =AB$22+(AB$22*H$39) -> 85562.494
B23: % of Total Income | C23: % | D23: =D22/D6 -> 0.9631412 | E23: =E22/E6 -> 0.97473955 | F23: =F22/F6 -> 0.97568696 | G23: =G22/G6 -> 0.97153368 | H23: =H22/H6 -> 0.95822398 | K23: =K22/K6 -> 0.95624635 | L23: =L22/L6 -> 0.95417958 | M23: =M22/M6 -> 0.9524681 | N23: =N22/N6 -> 0.95069601 | O23: =O22/O6 -> 0.94933273 | R23: =R22/R6 -> 0.955804 | S23: =S22/S6 -> 0.95325068 | T23: =T22/T6 -> 0.95148903 | U23: =U22/U6 -> 0.94966451 | V23: =V22/V6 -> 0.94826065 | Y23: =Y22/Y6 -> 0.95599396 | Z23: =Z22/Z6 -> 0.95365066 | AA23: =AA22/AA6 -> 0.9514235 | AB23: =AB22/AB6 -> 0.94909503 | AC23: =AC22/AC6 -> 0.94766213
B25: OTHER INCOME | K25: OTHER INCOME - FORECAST (BEST CASE) | R25: OTHER INCOME - FORECAST (BASE CASE) | Y25: OTHER INCOME - FORECAST (WORST CASE)
B28: Other Income | C28: ₹ | D28: ='PROFIT & LOSS'!D8 -> 2382 | E28: ='PROFIT & LOSS'!E8 -> 2061 | F28: ='PROFIT & LOSS'!F8 -> 2266 | G28: ='PROFIT & LOSS'!G8 -> 2631 | H28: ='PROFIT & LOSS'!H8 -> 3884 | K28: =$H$28+($H$28*K29) -> 4117.04 | L28: =K$28+(K$28*L$29) -> 4364.0624 | M28: =L$28+(L$28*M$29) -> 4625.9061 | N28: =M$28+(M$28*N$29) -> 4903.4605 | O28: =N$28+(N$28*O$29) -> 5197.6681 | R28: =$H$28+($H$28*$R$29) -> 4078.2 | S28: =R$28+(R$28*S$29) -> 4282.11 | T28: =S$28+(S$28*T$29) -> 4496.2155 | U28: =T$28+(T$28*U$29) -> 4721.0263 | V28: =U$28+(U$28*V$29) -> 4957.0776 | Y28: =$H$28+($H$28*$Y$29) -> 4039.36 | Z28: =Y$28+(Y$28*Z$29) -> 4200.9344 | AA28: =Z$28+(Z$28*AA$29) -> 4368.9718 | AB28: =AA$28+(AA$28*AB$29) -> 4543.7306 | AC28: =AB$28+(AB$28*AC$29) -> 4725.4799
B29: YoY change | C29: % | D29: N/A | E29: =E28/D28-1 -> -0.13476071 | F29: =F28/E28-1 -> 0.099466279 | G29: =G28/F28-1 -> 0.16107679 | H29: =H28/G28-1 -> 0.47624477 | K29: =D$49 -> 0.06 | L29: =E$49 -> 0.06 | M29: =F$49 -> 0.06 | N29: =G$49 -> 0.06 | O29: =H$49 -> 0.06 | R29: =D$50 -> 0.05 | S29: =E$50 -> 0.05 | T29: =F$50 -> 0.05 | U29: =G$50 -> 0.05 | V29: =H$50 -> 0.05 | Y29: =D$51 -> 0.04 | Z29: =E$51 -> 0.04 | AA29: =F$51 -> 0.04 | AB29: =G$51 -> 0.04 | AC29: =H$51 -> 0.04
B30: % of Total Income | C30: % | D30: =D28/D6 -> 0.036858801 | E30: =E28/E6 -> 0.025260449 | F30: =F28/F6 -> 0.024313044 | G30: =G28/G6 -> 0.028466324 | H30: =H28/H6 -> 0.041776019 | K30: =K28/K6 -> 0.043753651 | L30: =L28/L6 -> 0.045820425 | M30: =M28/M6 -> 0.047531895 | N30: =N28/N6 -> 0.049303989 | O30: =O28/O6 -> 0.050667267 | R30: =R28/R6 -> 0.044196 | S30: =S28/S6 -> 0.046749325 | T30: =T28/T6 -> 0.048510967 | U30: =U28/U6 -> 0.050335488 | V30: =V28/V6 -> 0.051739345 | Y30: =Y28/Y6 -> 0.044006038 | Z30: =Z28/Z6 -> 0.046349339 | AA30: =AA28/AA6 -> 0.048576503 | AB30: =AB28/AB6 -> 0.050904974 | AC30: =AC28/AC6 -> 0.052337866
D31: Revenue Assumption | K31: COGS & OpEx Assumption & Interest | R31: Depreciation Assumption & Interest | Y31: Tax Assumption
B32: ASSUMPTIONS
D33: Year 1 | E33: Year 2 | F33: Year 3 | G33: Year 4 | H33: Year 5 | K33: Year 1 | L33: Year 2 | M33: Year 3 | N33: Year 4 | O33: Year 5 | R33: Year 1 | S33: Year 2 | T33: Year 3 | U33: Year 4 | V33: Year 5 | Y33: Year 1 | Z33: Year 2 | AA33: Year 3 | AB33: Year 4 | AC33: Year 5
B35: Revenue from Operations CAGR | K35: Cogs % of Rev | R35: Dep. % of PPE | Y35: Tax % of EBT
B37: Best Case | C37: % | D37: 0.01 | E37: 0.01 | F37: 0.02 | G37: 0.02 | H37: 0.03 | K37: 0.71 | L37: 0.71 | M37: 0.71 | N37: 0.71 | O37: 0.71 | R37: 0.15 | S37: 0.151 | T37: 0.152 | U37: 0.153 | V37: 0.154 | Y37: 0.23 | Z37: 0.23 | AA37: 0.23 | AB37: 0.23 | AC37: 0.23
B38: Base Case | C38: % | D38: -0.01 | E38: -0.01 | F38: 0.01 | G38: 0.01 | H38: 0.02 | K38: 0.72 | L38: 0.72 | M38: 0.72 | N38: 0.72 | O38: 0.72 | R38: 0.145 | S38: 0.146 | T38: 0.147 | U38: 0.148 | V38: 0.149 | Y38: 0.24 | Z38: 0.24 | AA38: 0.24 | AB38: 0.24 | AC38: 0.24
B39: Worst Case | C39: % | D39: -0.015 | E39: -0.015 | F39: -0.01 | G39: -0.01 | H39: 0.01 | K39: 0.73 | L39: 0.73 | M39: 0.73 | N39: 0.73 | O39: 0.73 | R39: 0.13 | S39: 0.131 | T39: 0.132 | U39: 0.133 | V39: 0.134 | Y39: 0.25 | Z39: 0.25 | AA39: 0.25 | AB39: 0.25 | AC39: 0.25
B41: IT Services % of Rev from Operations | K41: Opex % of TI | R41: Ac. D % of TI | Y41: Dividend %
B43: Best Case | C43: % | D43: 0.997 | E43: 0.997 | F43: 0.997 | G43: 0.997 | H43: 0.997 | K43: 0.06 | L43: 0.06 | M43: 0.06 | N43: 0.06 | O43: 0.06 | R43: N/A | S43: 0.149 | T43: 0.148 | U43: 0.147 | V43: 0.146 | Y43: 0.15 | Z43: 0.2 | AA43: 0.25 | AB43: 0.25 | AC43: 0.25
B44: Base Case | C44: % | D44: 0.998 | E44: 0.998 | F44: 0.998 | G44: 0.998 | H44: 0.998 | K44: 0.063 | L44: 0.063 | M44: 0.063 | N44: 0.063 | O44: 0.063 | R44: N/A | S44: 0.153 | T44: 0.152 | U44: 0.151 | V44: 0.15 | Y44: 0.2 | Z44: 0.25 | AA44: 0.3 | AB44: 0.3 | AC44: 0.3
B45: Worst Case | C45: % | D45: 0.999 | E45: 0.999 | F45: 0.999 | G45: 0.999 | H45: 0.999 | K45: 0.066 | L45: 0.066 | M45: 0.066 | N45: 0.066 | O45: 0.066 | R45: N/A | S45: 0.159 | T45: 0.159 | U45: 0.159 | V45: 0.159 | Y45: 0.3 | Z45: 0.35 | AA45: 0.4 | AB45: 0.45 | AC45: 0.5
B47: Other Income YoY Change % | K47: Std % of Debt | R47: Ltd % of Debt | Y47: Weighted O.S
B49: Best Case | C49: % | D49: 0.06 | E49: 0.06 | F49: 0.06 | G49: 0.06 | H49: 0.06 | K49: 0.54 | L49: 0.52 | M49: 0.5 | N49: 0.48 | O49: 0.46 | R49: =100%-K49 -> 0.46 | S49: =100%-L49 -> 0.48 | T49: =100%-M49 -> 0.5 | U49: =100%-N49 -> 0.52 | V49: =100%-O49 -> 0.54 | Y49: -0.003 | Z49: -0.003 | AA49: -0.003 | AB49: -0.003 | AC49: -0.003
B50: Base Case | C50: % | D50: 0.05 | E50: 0.05 | F50: 0.05 | G50: 0.05 | H50: 0.05 | K50: 0.58 | L50: 0.56 | M50: 0.54 | N50: 0.52 | O50: 0.5 | R50: =100%-K50 -> 0.42 | S50: =100%-L50 -> 0.44 | T50: =100%-M50 -> 0.46 | U50: =100%-N50 -> 0.48 | V50: =100%-O50 -> 0.5 | Y50: 0.03 | Z50: 0.03 | AA50: 0.03 | AB50: 0.03 | AC50: 0.03
B51: Worst Case | C51: % | D51: 0.04 | E51: 0.04 | F51: 0.04 | G51: 0.04 | H51: 0.04 | K51: 0.59 | L51: 0.6 | M51: 0.6 | N51: 0.6 | O51: 0.6 | R51: =100%-K51 -> 0.41 | S51: =100%-L51 -> 0.4 | T51: =100%-M51 -> 0.4 | U51: =100%-N51 -> 0.4 | V51: =100%-O51 -> 0.4 | Y51: 0.05 | Z51: 0.05 | AA51: 0.05 | AB51: 0.05 | AC51: 0.05
B53: COGS & OPEX | K53: COGS & OPEX - FORECAST (BEST CASE) | R53: COGS & OPEX - FORECAST (BASE CASE) | Y53: COGS & OPEX - FORECAST (WORST CASE)
B56: COGS | C56: ₹ | D56: ='PROFIT & LOSS'!D$12 -> 44351 | E56: ='PROFIT & LOSS'!E$12 -> 59072 | F56: ='PROFIT & LOSS'!F$12 -> 67302 | G56: ='PROFIT & LOSS'!G$12 -> 67100 | H56: ='PROFIT & LOSS'!H$12 -> 65287 | K56: =K58*K22 -> 63885.005 | L56: =L58*L22 -> 64523.855 | M56: =M58*M22 -> 65814.332 | N56: =N58*N22 -> 67130.619 | O56: =O58*O22 -> 69144.537 | R56: =R58*R22 -> 63501.926 | S56: =S58*S22 -> 62866.907 | T56: =T58*T22 -> 63495.576 | U56: =U58*U22 -> 64130.532 | V56: =V58*V22 -> 65413.143 | Y56: =Y58*Y22 -> 64058.726 | Z56: =Z58*Z22 -> 63097.846 | AA56: =AA58*AA22 -> 62466.867 | AB56: =AB58*AB22 -> 61842.198 | AC56: =AC58*AC22 -> 62460.62
B57: YoY change | C57: % | D57: N/A | E57: =E56/D56-1 -> 0.33192036 | F57: =F56/E56-1 -> 0.13932151 | G57: =G56/F56-1 -> -0.0030013967 | H57: =H56/G56-1 -> -0.027019374 | K57: =$K$56/$H$56-1 -> -0.021474339 | L57: =L56/K56-1 -> 0.01 | M57: =M56/L56-1 -> 0.02 | N57: =N56/M56-1 -> 0.02 | O57: =O56/N56-1 -> 0.03 | R57: =$R$56/$H$56-1 -> -0.027341946 | S57: =S56/R56-1 -> -0.01 | T57: =T56/S56-1 -> 0.01 | U57: =U56/T56-1 -> 0.01 | V57: =V56/U56-1 -> 0.02 | Y57: =$Y$56/$H$56-1 -> -0.018813448 | Z57: =Z56/Y56-1 -> -0.015 | AA57: =AA56/Z56-1 -> -0.01 | AB57: =AB56/AA56-1 -> -0.01 | AC57: =AC56/AB56-1 -> 0.01
B58: % of Rev | C58: % | D58: =D56/D22 -> 0.71254599 | E58: =E56/E22 -> 0.74277308 | F58: =F56/F22 -> 0.74011107 | G58: =G56/G22 -> 0.74726596 | H58: =H56/H22 -> 0.73283719 | K58: =K$37 -> 0.71 | L58: =L$37 -> 0.71 | M58: =M$37 -> 0.71 | N58: =N$37 -> 0.71 | O58: =O$37 -> 0.71 | R58: =K$38 -> 0.72 | S58: =L$38 -> 0.72 | T58: =M$38 -> 0.72 | U58: =N$38 -> 0.72 | V58: =O$38 -> 0.72 | Y58: =K$39 -> 0.73 | Z58: =L$39 -> 0.73 | AA58: =M$39 -> 0.73 | AB58: =N$39 -> 0.73 | AC58: =O$39 -> 0.73
B60: OPEX | C60: ₹ | D60: ='PROFIT & LOSS'!D$18 -> 2812 | E60: ='PROFIT & LOSS'!E$18 -> 4924 | F60: ='PROFIT & LOSS'!F$18 -> 6279 | G60: ='PROFIT & LOSS'!G$18 -> 5886 | H60: ='PROFIT & LOSS'!H$18 -> 5781 | K60: =K62*K6 -> 5645.7552 | L60: =L62*L6 -> 5714.5639 | M60: =M62*M6 -> 5839.3289 | N60: =N62*N6 -> 5967.2177 | O60: =O62*O6 -> 6155.0604 | R60: =R62*R6 -> 5813.3452 | S60: =S62*S6 -> 5770.6273 | T60: =T62*T6 -> 5839.1245 | U60: =U62*U6 -> 5908.8462 | V60: =V62*V6 -> 6035.9459 | Y60: =Y62*Y6 -> 6058.2086 | Z60: =Z62*Z6 -> 5981.9984 | AA60: =AA62*AA6 -> 5936.0415 | AB60: =AB62*AB6 -> 5891.0987 | AC60: =AC62*AC6 -> 5959.0063
B61: YoY change | C61: % | D61: N/A | E61: =E60/D60-1 -> 0.75106686 | F61: =F60/E60-1 -> 0.27518278 | G61: =G60/F60-1 -> -0.062589584 | H61: =H60/G60-1 -> -0.01783894 | K61: =$K$60/$H$60-1 -> -0.023394707 | L61: =L60/K60-1 -> 0.012187683 | M61: =M60/L60-1 -> 0.021832817 | N61: =N60/M60-1 -> 0.021901276 | O61: =O60/N60-1 -> 0.03147912 | R61: =$R$60/$H$60-1 -> 0.0055950804 | S61: =S60/R60-1 -> -0.00734824 | T61: =T60/S60-1 -> 0.011869973 | U61: =U60/T60-1 -> 0.011940439 | V61: =V60/U60-1 -> 0.021510065 | Y61: =$Y$60/$H$60-1 -> 0.047951676 | Z61: =Z60/Y60-1 -> -0.012579668 | AA61: =AA60/Z60-1 -> -0.0076825331 | AB61: =AB60/AA60-1 -> -0.0075711748 | AC61: =AC60/AB60-1 -> 0.011527149
B62: % of Total Income | C62: % | D62: =D60/D6 -> 0.043512573 | E62: =E60/E6 -> 0.060350533 | F62: =F60/F6 -> 0.067370522 | G62: =G60/G6 -> 0.063684068 | H62: =H60/H6 -> 0.062180011 | K62: =K$43 -> 0.06 | L62: =L$43 -> 0.06 | M62: =M$43 -> 0.06 | N62: =N$43 -> 0.06 | O62: =O$43 -> 0.06 | R62: =K$44 -> 0.063 | S62: =L$44 -> 0.063 | T62: =M$44 -> 0.063 | U62: =N$44 -> 0.063 | V62: =O$44 -> 0.063 | Y62: =K$45 -> 0.066 | Z62: =L$45 -> 0.066 | AA62: =M$45 -> 0.066 | AB62: =N$45 -> 0.066 | AC62: =O$45 -> 0.066
...

Sheet PROFIT & LOSS
B1: WIPRO | D1: INCOME STATEMENT | I1: 2 | K1: INCOME STATEMENT - FORECAST
C3: UNIT | D3: Year 1 | E3: Year 2 | F3: Year 3 | G3: Year 4 | H3: Year 5 | K3: Year 6 | L3: Year 7 | M3: Year 8 | N3: Year 9 | O3: Year 10
B4: Particulars (In Crores) | D4: 44276 | E4: =EDATE(D4,12) -> 44641 | F4: =EDATE(E4,12) -> 45006 | G4: =EDATE(F4,12) -> 45372 | H4: =EDATE(G4,12) -> 45737 | K4: =EDATE(H4,12) -> 46102 | L4: =EDATE(K4,12) -> 46467 | M4: =EDATE(L4,12) -> 46833 | N4: =EDATE(M4,12) -> 47198 | O4: =EDATE(N4,12) -> 47563
B6: Revenue from Operations | C6: ₹ | D6: =STATEMENTS!C63 -> 62243 | E6: =STATEMENTS!D63 -> 79529 | F6: =STATEMENTS!E63 -> 90935 | G6: =STATEMENTS!F63 -> 89794 | H6: =STATEMENTS!G63 -> 89088 | K6: =CHOOSE($I$1,'P & L ASSUMPTIONS'!K$22,'P & L ASSUMPTIONS'!R$22,'P & L ASSUMPTIONS'!Y$22) -> 88197.12 | L6: =CHOOSE($I$1,'P & L ASSUMPTIONS'!L$22,'P & L ASSUMPTIONS'!S$22,'P & L ASSUMPTIONS'!Z$22) -> 87315.149 | M6: =CHOOSE($I$1,'P & L ASSUMPTIONS'!M$22,'P & L ASSUMPTIONS'!T$22,'P & L ASSUMPTIONS'!AA$22) -> 88188.3 | N6: =CHOOSE($I$1,'P & L ASSUMPTIONS'!N$22,'P & L ASSUMPTIONS'!U$22,'P & L ASSUMPTIONS'!AB$22) -> 89070.183 | O6: =CHOOSE($I$1,'P & L ASSUMPTIONS'!O$22,'P & L ASSUMPTIONS'!V$22,'P & L ASSUMPTIONS'!AC$22) -> 90851.587
B8: Other Income | C8: ₹ | D8: =STATEMENTS!C64 -> 2382 | E8: =STATEMENTS!D64 -> 2061 | F8: =STATEMENTS!E64 -> 2266 | G8: =STATEMENTS!F64 -> 2631 | H8: =STATEMENTS!G64 -> 3884 | K8: =CHOOSE($I$1,'P & L ASSUMPTIONS'!K$28,'P & L ASSUMPTIONS'!R$28,'P & L ASSUMPTIONS'!Y$28) -> 4078.2 | L8: =CHOOSE($I$1,'P & L ASSUMPTIONS'!L$28,'P & L ASSUMPTIONS'!S$28,'P & L ASSUMPTIONS'!Z$28) -> 4282.11 | M8: =CHOOSE($I$1,'P & L ASSUMPTIONS'!M$28,'P & L ASSUMPTIONS'!T$28,'P & L ASSUMPTIONS'!AA$28) -> 4496.2155 | N8: =CHOOSE($I$1,'P & L ASSUMPTIONS'!N$28,'P & L ASSUMPTIONS'!U$28,'P & L ASSUMPTIONS'!AB$28) -> 4721.0263 | O8: =CHOOSE($I$1,'P & L ASSUMPTIONS'!O$28,'P & L ASSUMPTIONS'!V$28,'P & L ASSUMPTIONS'!AC$28) -> 4957.0776
B10: Total Income | C10: ₹ | D10: =D6+D8 -> 64625 | E10: =E6+E8 -> 81590 | F10: =F6+F8 -> 93201 | G10: =G6+G8 -> 92425 | H10: =H6+H8 -> 92972 | K10: =K6+K8 -> 92275.32 | L10: =L6+L8 -> 91597.259 | M10: =M6+M8 -> 92684.516 | N10: =N6+N8 -> 93791.21 | O10: =O6+O8 -> 95808.665
B12: COGS | C12: ₹ | D12: =STATEMENTS!C67+STATEMENTS!C68+STATEMENTS!C72+STATEMENTS!C73+STATEMENTS!C69 -> 44351 | E12: =STATEMENTS!D67+STATEMENTS!D68+STATEMENTS!D72+STATEMENTS!D73+STATEMENTS!D69 -> 59072 | F12: =STATEMENTS!E67+STATEMENTS!E68+STATEMENTS!E72+STATEMENTS!E73+STATEMENTS!E69 -> 67302 | G12: =STATEMENTS!F67+STATEMENTS!F68+STATEMENTS!F72+STATEMENTS!F73+STATEMENTS!F69 -> 67100 | H12: =STATEMENTS!G67+STATEMENTS!G68+STATEMENTS!G72+STATEMENTS!G73+STATEMENTS!G69 -> 65287 | K12: =CHOOSE($I$1,'P & L ASSUMPTIONS'!K56,'P & L ASSUMPTIONS'!R56,'P & L ASSUMPTIONS'!Y56) -> 63501.926 | L12: =CHOOSE($I$1,'P & L ASSUMPTIONS'!L56,'P & L ASSUMPTIONS'!S56,'P & L ASSUMPTIONS'!Z56) -> 62866.907 | M12: =CHOOSE($I$1,'P & L ASSUMPTIONS'!M56,'P & L ASSUMPTIONS'!T56,'P & L ASSUMPTIONS'!AA56) -> 63495.576 | N12: =CHOOSE($I$1,'P & L ASSUMPTIONS'!N56,'P & L ASSUMPTIONS'!U56,'P & L ASSUMPTIONS'!AB56) -> 64130.532 | O12: =CHOOSE($I$1,'P & L ASSUMPTIONS'!O56,'P & L ASSUMPTIONS'!V56,'P & L ASSUMPTIONS'!AC56) -> 65413.143
B13: % of Rev | C13: % | D13: =D12/D6 -> 0.71254599 | E13: =E12/E6 -> 0.74277308 | F13: =F12/F6 -> 0.74011107 | G13: =G12/G6 -> 0.74726596 | H13: =H12/H6 -> 0.73283719 | K13: =K12/K6 -> 0.72 | L13: =L12/L6 -> 0.72 | M13: =M12/M6 -> 0.72 | N13: =N12/N6 -> 0.72 | O13: =O12/O6 -> 0.72
B15: Gross Profit | C15: ₹ | D15: =D10-D12 -> 20274 | E15: =E10-E12 -> 22518 | F15: =F10-F12 -> 25899 | G15: =G10-G12 -> 25325 | H15: =H10-H12 -> 27685 | K15: =K10-K12 -> 28773.394 | L15: =L10-L12 -> 28730.352 | M15: =M10-M12 -> 29188.94 | N15: =N10-N12 -> 29660.678 | O15: =O10-O12 -> 30395.522
B16: % of Rev | C16: % | D16: =D15/D6 -> 0.32572337 | E16: =E15/E6 -> 0.283142 | F16: =F15/F6 -> 0.28480783 | G16: =G15/G6 -> 0.28203443 | H16: =H15/H6 -> 0.31076015 | K16: =K15/K6 -> 0.32623961 | L16: =L15/L6 -> 0.32904201 | M16: =M15/M6 -> 0.33098426 | N16: =N15/N6 -> 0.33300344 | O16: =O15/O6 -> 0.33456237
B18: Other Expenses | C18: ₹ | D18: =SUM(STATEMENTS!C74:C80) -> 2812 | E18: =SUM(STATEMENTS!D74:D80) -> 4924 | F18: =SUM(STATEMENTS!E74:E80) -> 6279 | G18: =SUM(STATEMENTS!F74:F80) -> 5886 | H18: =SUM(STATEMENTS!G74:G80) -> 5781 | K18: =CHOOSE($I$1,'P & L ASSUMPTIONS'!K60,'P & L ASSUMPTIONS'!R60,'P & L ASSUMPTIONS'!Y60) -> 5813.3452 | L18: =CHOOSE($I$1,'P & L ASSUMPTIONS'!L60,'P & L ASSUMPTIONS'!S60,'P & L ASSUMPTIONS'!Z60) -> 5770.6273 | M18: =CHOOSE($I$1,'P & L ASSUMPTIONS'!M60,'P & L ASSUMPTIONS'!T60,'P & L ASSUMPTIONS'!AA60) -> 5839.1245 | N18: =CHOOSE($I$1,'P & L ASSUMPTIONS'!N60,'P & L ASSUMPTIONS'!U60,'P & L ASSUMPTIONS'!AB60) -> 5908.8462 | O18: =CHOOSE($I$1,'P & L ASSUMPTIONS'!O60,'P & L ASSUMPTIONS'!V60,'P & L ASSUMPTIONS'!AC60) -> 6035.9459
B19: % of Total Income | C19: % | D19: =D18/D10 -> 0.043512573 | E19: =E18/E10 -> 0.060350533 | F19: =F18/F10 -> 0.067370522 | G19: =G18/G10 -> 0.063684068 | H19: =H18/H10 -> 0.062180011 | K19: =K18/K10 -> 0.063 | L19: =L18/L10 -> 0.063 | M19: =M18/M10 -> 0.063 | N19: =N18/N10 -> 0.063 | O19: =O18/O10 -> 0.063
B21: EBITDA | C21: ₹ | D21: =D15-D18 -> 17462 | E21: =E15-E18 -> 17594 | F21: =F15-F18 -> 19620 | G21: =G15-G18 -> 19439 | H21: =H15-H18 -> 21904 | K21: =K15-K18 -> 22960.048 | L21: =L15-L18 -> 22959.724 | M21: =M15-M18 -> 23349.815 | N21: =N15-N18 -> 23751.831 | O21: =O15-O18 -> 24359.576
B22: % of Total Income | C22: % | D22: =D21/D10 -> 0.27020503 | E22: =E21/E10 -> 0.21563917 | F22: =F21/F10 -> 0.21051276 | G22: =G21/G10 -> 0.21032188 | H22: =H21/H10 -> 0.23559781 | K22: =K21/K10 -> 0.24882112 | L22: =L21/L10 -> 0.25065951 | M22: =M21/M10 -> 0.2519279 | N22: =N21/N10 -> 0.25324155 | O22: =O21/O10 -> 0.25425233
B24: D & A | C24: ₹ | D24: =STATEMENTS!C71 -> 2763 | E24: =STATEMENTS!D71 -> 3078 | F24: =STATEMENTS!E71 -> 3340 | G24: =STATEMENTS!F71 -> 3407 | H24: =STATEMENTS!G71 -> 2958 | K24: =CHOOSE($I$1,'P & L ASSUMPTIONS'!K70,'P & L ASSUMPTIONS'!R70,'P & L ASSUMPTIONS'!Y70) -> 3265.835 | L24: =CHOOSE($I$1,'P & L ASSUMPTIONS'!L70,'P & L ASSUMPTIONS'!S70,'P & L ASSUMPTIONS'!Z70) -> 3323.8395 | M24: =CHOOSE($I$1,'P & L ASSUMPTIONS'!M70,'P & L ASSUMPTIONS'!T70,'P & L ASSUMPTIONS'!AA70) -> 3373.7128 | N24: =CHOOSE($I$1,'P & L ASSUMPTIONS'!N70,'P & L ASSUMPTIONS'!U70,'P & L ASSUMPTIONS'!AB70) -> 3424.996 | O24: =CHOOSE($I$1,'P & L ASSUMPTIONS'!O70,'P & L ASSUMPTIONS'!V70,'P & L ASSUMPTIONS'!AC70) -> 3477.628
B25: % of Total Income | C25: % | D25: =D24/D10 -> 0.042754352 | E25: =E24/E10 -> 0.037725211 | F25: =F24/F10 -> 0.035836525 | G25: =G24/G10 -> 0.036862321 | H25: =H24/H10 -> 0.031816031 | K25: =K24/K10 -> 0.035392291 | L25: =L24/L10 -> 0.036287543 | M25: =M24/M10 -> 0.036399961 | N25: =N24/N10 -> 0.036517239 | O25: =O24/O10 -> 0.036297636
B27: EBIT | C27: ₹ | D27: =D21-D24 -> 14699 | E27: =E21-E24 -> 14516 | F27: =F21-F24 -> 16280 | G27: =G21-G24 -> 16032 | H27: =H21-H24 -> 18946 | K27: =K21-K24 -> 19694.213 | L27: =L21-L24 -> 19635.885 | M27: =M21-M24 -> 19976.102 | N27: =N21-N24 -> 20326.835 | O27: =O21-O24 -> 20881.948
B28: % of Total Income | C28: % | D28: =D27/D10 -> 0.22745068 | E28: =E27/E10 -> 0.17791396 | F28: =F27/F10 -> 0.17467624 | G28: =G27/G10 -> 0.17345956 | H28: =H27/H10 -> 0.20378178 | K28: =K27/K10 -> 0.21342883 | L28: =L27/L10 -> 0.21437197 | M28: =M27/M10 -> 0.21552794 | N28: =N27/N10 -> 0.21672431 | O28: =O27/O10 -> 0.21795469
B30: Interest | C30: ₹ | D30: =STATEMENTS!C70 -> 509 | E30: =STATEMENTS!D70 -> 535 | F30: =STATEMENTS!E70 -> 1077 | G30: =STATEMENTS!F70 -> 1255 | H30: =STATEMENTS!G70 -> 1477 | K30: =CHOOSE($I$1,'P & L ASSUMPTIONS'!K82,'P & L ASSUMPTIONS'!R82,'P & L ASSUMPTIONS'!Y82) -> 1893.177 | L30: =CHOOSE($I$1,'P & L ASSUMPTIONS'!L82,'P & L ASSUMPTIONS'!S82,'P & L ASSUMPTIONS'!Z82) -> 1904.877 | M30: =CHOOSE($I$1,'P & L ASSUMPTIONS'!M82,'P & L ASSUMPTIONS'!T82,'P & L ASSUMPTIONS'!AA82) -> 1918.917 | N30: =CHOOSE($I$1,'P & L ASSUMPTIONS'!N82,'P & L ASSUMPTIONS'!U82,'P & L ASSUMPTIONS'!AB82) -> 1935.297 | O30: =CHOOSE($I$1,'P & L ASSUMPTIONS'!O82,'P & L ASSUMPTIONS'!V82,'P & L ASSUMPTIONS'!AC82) -> 1954.017
B32: EBT | C32: ₹ | D32: =D27-D30 -> 14190 | E32: =E27-E30 -> 13981 | F32: =F27-F30 -> 15203 | G32: =G27-G30 -> 14777 | H32: =H27-H30 -> 17469 | K32: =K27-K30 -> 17801.036 | L32: =L27-L30 -> 17731.008 | M32: =M27-M30 -> 18057.185 | N32: =N27-N30 -> 18391.538 | O32: =O27-O30 -> 18927.931
B33: % of Total Income | C33: % | D33: =D32/D10 -> 0.21957447 | E33: =E32/E10 -> 0.17135678 | F33: =F32/F10 -> 0.16312057 | G33: =G32/G10 -> 0.15988098 | H33: =H32/H10 -> 0.18789528 | K33: =K32/K10 -> 0.19291222 | L33: =L32/L10 -> 0.19357575 | M33: =M32/M10 -> 0.19482419 | N33: =N32/N10 -> 0.19609021 | O33: =O32/O10 -> 0.1975597
B35: Tax | C35: ₹ | D35: =STATEMENTS!C85 -> 3035 | E35: =STATEMENTS!D85 -> 2897 | F35: =STATEMENTS!E85 -> 3399 | G35: =STATEMENTS!F85 -> 3609 | H35: =STATEMENTS!G85 -> 4278 | K35: =CHOOSE($I$1,'P & L ASSUMPTIONS'!K99,'P & L ASSUMPTIONS'!R99,'P & L ASSUMPTIONS'!Y99) -> 4272.2487 | L35: =CHOOSE($I$1,'P & L ASSUMPTIONS'!L99,'P & L ASSUMPTIONS'!S99,'P & L ASSUMPTIONS'!Z99) -> 4255.4419 | M35: =CHOOSE($I$1,'P & L ASSUMPTIONS'!M99,'P & L ASSUMPTIONS'!T99,'P & L ASSUMPTIONS'!AA99) -> 4333.7245 | N35: =CHOOSE($I$1,'P & L ASSUMPTIONS'!N99,'P & L ASSUMPTIONS'!U99,'P & L ASSUMPTIONS'!AB99) -> 4413.9692 | O35: =CHOOSE($I$1,'P & L ASSUMPTIONS'!O99,'P & L ASSUMPTIONS'!V99,'P & L ASSUMPTIONS'!AC99) -> 4542.7035
B36: Effective Tax Rate | C36: % | D36: =D35/D32 -> 0.21388302 | E36: =E35/E32 -> 0.20720978 | F36: =F35/F32 -> 0.22357429 | G36: =G35/G32 -> 0.2442309 | H36: =H35/H32 -> 0.24489095 | K36: =K35/K32 -> 0.24 | L36: =L35/L32 -> 0.24 | M36: =M35/M32 -> 0.24 | N36: =N35/N32 -> 0.24 | O36: =O35/O32 -> 0.24
B38: Net Profit | C38: ₹ | D38: =D32-D35 -> 11155 | E38: =E32-E35 -> 11084 | F38: =F32-F35 -> 11804 | G38: =G32-G35 -> 11168 | H38: =H32-H35 -> 13191 | K38: =K32-K35 -> 13528.788 | L38: =L32-L35 -> 13475.566 | M38: =M32-M35 -> 13723.461 | N38: =N32-N35 -> 13977.569 | O38: =O32-O35 -> 14385.228
B39: % of Total Income | C39: % | D39: =D38/D10 -> 0.17261122 | E39: =E38/E10 -> 0.13584998 | F39: =F38/F10 -> 0.126651 | G39: =G38/G10 -> 0.12083311 | H39: =H38/H10 -> 0.14188143 | K39: =K38/K10 -> 0.14661328 | L39: =L38/L10 -> 0.14711757 | M39: =M38/M10 -> 0.14806638 | N39: =N38/N10 -> 0.14902856 | O39: =O38/O10 -> 0.15014537
B41: Weighted Avg. Outstanding Shares | C41: ₹ | D41: 1048.89 | E41: 1061.14 | F41: 548.9 | G41: 548.21 | H41: 566.17 | K41: =CHOOSE($I$1,'PROFIT & LOSS'!$H$41+$H$41*'P & L ASSUMPTIONS'!Y$49,'PROFIT & LOSS'!$H$41+'PROFIT & LOSS'!$H$41*'P & L ASSUMPTIONS'!Y$50,'PROFIT & LOSS'!$H$41+'PROFIT & LOSS'!$H$41*'P & L ASSUMPTIONS'!Y$51) -> 583.1551 | L41: =CHOOSE($I$1,K$41+K$41*'P & L ASSUMPTIONS'!Z$49,'PROFIT & LOSS'!K$41+'PROFIT & LOSS'!K$41*'P & L ASSUMPTIONS'!Z$50,'PROFIT & LOSS'!K$41+'PROFIT & LOSS'!K$41*'P & L ASSUMPTIONS'!Z$51) -> 600.64975 | M41: =CHOOSE($I$1,L$41+L$41*'P & L ASSUMPTIONS'!AA$49,'PROFIT & LOSS'!L$41+'PROFIT & LOSS'!L$41*'P & L ASSUMPTIONS'!AA$50,'PROFIT & LOSS'!L$41+'PROFIT & LOSS'!L$41*'P & L ASSUMPTIONS'!AA$51) -> 618.66925 | N41: =CHOOSE($I$1,M$41+M$41*'P & L ASSUMPTIONS'!AB$49,'PROFIT & LOSS'!M$41+'PROFIT & LOSS'!M$41*'P & L ASSUMPTIONS'!AB$50,'PROFIT & LOSS'!M$41+'PROFIT & LOSS'!M$41*'P & L ASSUMPTIONS'!AB$51) -> 637.22932 | O41: =CHOOSE($I$1,N$41+N$41*'P & L ASSUMPTIONS'!AC$49,'PROFIT & LOSS'!N$41+'PROFIT & LOSS'!N$41*'P & L ASSUMPTIONS'!AC$50,'PROFIT & LOSS'!N$41+'PROFIT & LOSS'!N$41*'P & L ASSUMPTIONS'!AC$51) -> 656.3462
B42: EPS | C42: ₹ | D42: =STATEMENTS!C90 -> 19.07 | E42: =STATEMENTS!D90 -> 22.31 | F42: =STATEMENTS!E90 -> 20.68 | G42: =STATEMENTS!F90 -> 10.41 | H42: =STATEMENTS!G90 -> 12.52 | K42: =K38/K41 -> 23.199296 | L42: =L38/L41 -> 22.434981 | M42: =M38/M41 -> 22.182226 | N42: =N38/N41 -> 21.934912 | O42: =O38/O41 -> 21.917134
B44: Dividend Paid | C44: ₹ | D44: =-STATEMENTS!C119 -> 546 | E44: =-STATEMENTS!D119 -> 547 | F44: =-STATEMENTS!E119 -> 3281 | G44: =-STATEMENTS!F119 -> 522 | H44: =-STATEMENTS!G119 -> 6275 | K44: =K38*K45 -> 2705.7575 | L44: =L38*L45 -> 3368.8915 | M44: =M38*M45 -> 4117.0383 | N44: =N38*N45 -> 4193.2708 | O44: =O38*O45 -> 4315.5683
B45: Dividend Payout Ratio | C45: % | D45: =D44/D38 -> 0.048946661 | E45: =E44/E38 -> 0.049350415 | F45: =F44/F38 -> 0.27795662 | G45: =G44/G38 -> 0.046740688 | H45: =H44/H38 -> 0.47570313 | K45: =CHOOSE($I$1,'P & L ASSUMPTIONS'!Y$43,'P & L ASSUMPTIONS'!Y$44,'P & L ASSUMPTIONS'!Y$45) -> 0.2 | L45: =CHOOSE($I$1,'P & L ASSUMPTIONS'!Z$43,'P & L ASSUMPTIONS'!Z$44,'P & L ASSUMPTIONS'!Z$45) -> 0.25 | M45: =CHOOSE($I$1,'P & L ASSUMPTIONS'!AA$43,'P & L ASSUMPTIONS'!AA$44,'P & L ASSUMPTIONS'!AA$45) -> 0.3 | N45: =CHOOSE($I$1,'P & L ASSUMPTIONS'!AB$43,'P & L ASSUMPTIONS'!AB$44,'P & L ASSUMPTIONS'!AB$45) -> 0.3 | O45: =CHOOSE($I$1,'P & L ASSUMPTIONS'!AC$43,'P & L ASSUMPTIONS'!AC$44,'P & L ASSUMPTIONS'!AC$45) -> 0.3
B47: Retained Earnings | C47: ₹ | D47: =D38-D44 -> 10609 | E47: =E38-E44 -> 10537 | F47: =F38-F44 -> 8523 | G47: =G38-G44 -> 10646 | H47: =H38-H44 -> 6916 | K47: =K38-K44 -> 10823.03 | L47: =L38-L44 -> 10106.674 | M47: =M38-M44 -> 9606.4226 | N47: =N38-N44 -> 9784.2984 | O47: =O38-O44 -> 10069.659
B48: % of Net Profit | C48: % | D48: =D47/D38 -> 0.95105334 | E48: =E47/E38 -> 0.95064958 | F48: =F47/F38 -> 0.72204338 | G48: =G47/G38 -> 0.95325931 | H48: =H47/H38 -> 0.52429687 | K48: =K47/K38 -> 0.8 | L48: =L47/L38 -> 0.75 | M48: =M47/M38 -> 0.7 | N48: =N47/N38 -> 0.7 | O48: =O47/O38 -> 0.7

Sheet BALANCE SHEET ASSUMPTION
B1: WIPRO | D1: BALANCE SHEET SCHEDULE | K1: BALANCE SHEET - FORECAST (BEST CASE) | R1: BALANCE SHEET - FORECAST (BASE CASE) | Y1: BALANCE SHEET - FORECAST (WORST CASE)
C3: UNIT | D3: Year 1 | E3: Year 2 | F3: Year 3 | G3: Year 4 | H3: Year 5 | K3: Year 6 | L3: Year 7 | M3: Year 8 | N3: Year 9 | O3: Year 10 | R3: Year 6 | S3: Year 7 | T3: Year 8 | U3: Year 9 | V3: Year 10 | Y3: Year 6 | Z3: Year 7 | AA3: Year 8 | AB3: Year 9 | AC3: Year 10
B4: Particulars | D4: ='PROFIT & LOSS'!D4 -> 44276 | E4: ='PROFIT & LOSS'!E4 -> 44641 | F4: ='PROFIT & LOSS'!F4 -> 45006 | G4: ='PROFIT & LOSS'!G4 -> 45372 | H4: ='PROFIT & LOSS'!H4 -> 45737 | K4: ='PROFIT & LOSS'!K4 -> 46102 | L4: ='PROFIT & LOSS'!L4 -> 46467 | M4: ='PROFIT & LOSS'!M4 -> 46833 | N4: ='PROFIT & LOSS'!N4 -> 47198 | O4: ='PROFIT & LOSS'!O4 -> 47563 | R4: =K$4 -> 46102 | S4: =L$4 -> 46467 | T4: =M$4 -> 46833 | U4: =N$4 -> 47198 | V4: =O$4 -> 47563 | Y4: =R$4 -> 46102 | Z4: =S$4 -> 46467 | AA4: =T$4 -> 46833 | AB4: =U$4 -> 47198 | AC4: =V$4 -> 47563
B6: PPE | K6: PPE - FORECAST (BEST CASE) | R6: PPE - FORECAST (BASE CASE) | Y6: PPE - FORECAST (WORST CASE)
B9: Opening Gross PPE | C9: ₹ | D9: =SUM('DATA SHEET'!I47:I53) -> 18395 | E9: =D15 -> 19902 | F9: =E15 -> 21461 | G9: =F15 -> 22865 | H9: =G15 -> 21752 | K9: =$H$15 -> 22523 | L9: =K$15 -> 23082.116 | M9: =L$15 -> 23608.426 | N9: =M$15 -> 24137.825 | O9: =N$15 -> 24671.231 | R9: =$K$9 -> 22523 | S9: =R15 -> 22766.024 | T9: =S15 -> 22950.427 | U9: =T15 -> 23141.865 | V9: =U15 -> 23339.785 | Y9: =$R$9 -> 22523 | Z9: =Y15 -> 22515.679 | AA9: =Z15 -> 22467.152 | AB9: =AA15 -> 22397.032 | AC9: =AB15 -> 22308.293
B10: Addition (CapEx) | C10: ₹ | D10: 3277 | E10: =('BALANCE SHEET'!E25-'BALANCE SHEET'!D25)+'PROFIT & LOSS'!E24 -> 3964 | F10: =('BALANCE SHEET'!F25-'BALANCE SHEET'!E25)+'PROFIT & LOSS'!F24 -> 4113 | G10: =('BALANCE SHEET'!G25-'BALANCE SHEET'!F25)+'PROFIT & LOSS'!G24 -> 2586 | H10: =('BALANCE SHEET'!H25-'BALANCE SHEET'!G25)+'PROFIT & LOSS'!H24 -> 3392 | K10: ='P & L ASSUMPTIONS'!K22*'BALANCE SHEET ASSUMPTION'!K11 -> 3149.2608 | L10: ='P & L ASSUMPTIONS'!L22*'BALANCE SHEET ASSUMPTION'!L11 -> 3180.7534 | M10: ='P & L ASSUMPTIONS'!M22*'BALANCE SHEET ASSUMPTION'!M11 -> 3244.3685 | N10: ='P & L ASSUMPTIONS'!N22*'BALANCE SHEET ASSUMPTION'!N11 -> 3309.2558 | O10: ='P & L ASSUMPTIONS'!O22*'BALANCE SHEET ASSUMPTION'!O11 -> 3408.5335 | R10: ='P & L ASSUMPTIONS'!R22*'BALANCE SHEET ASSUMPTION'!R11 -> 2945.7838 | S10: ='P & L ASSUMPTIONS'!S22*'BALANCE SHEET ASSUMPTION'!S11 -> 2916.326 | T10: ='P & L ASSUMPTIONS'!T22*'BALANCE SHEET ASSUMPTION'!T11 -> 2945.4892 | U10: ='P & L ASSUMPTIONS'!U22*'BALANCE SHEET ASSUMPTION'!U11 -> 2974.9441 | V10: ='P & L ASSUMPTIONS'!V22*'BALANCE SHEET ASSUMPTION'!V11 -> 3034.443 | Y10: ='P & L ASSUMPTIONS'!Y22*'BALANCE SHEET ASSUMPTION'!Y11 -> 2808.0538 | Z10: ='P & L ASSUMPTIONS'!Z22*'BALANCE SHEET ASSUMPTION'!Z11 -> 2765.933 | AA10: ='P & L ASSUMPTIONS'!AA22*'BALANCE SHEET ASSUMPTION'!AA11 -> 2738.2736 | AB10: ='P & L ASSUMPTIONS'!AB22*'BALANCE SHEET ASSUMPTION'!AB11 -> 2710.8909 | AC10: ='P & L ASSUMPTIONS'!AC22*'BALANCE SHEET ASSUMPTION'!AC11 -> 2737.9998
B11: % of Rev from OP | C11: % | D11: =D10/'PROFIT & LOSS'!D6 -> 0.052648491 | E11: =E10/'PROFIT & LOSS'!E6 -> 0.049843453 | F11: =F10/'PROFIT & LOSS'!F6 -> 0.045230109 | G11: =G10/'PROFIT & LOSS'!G6 -> 0.028799252 | H11: =H10/'PROFIT & LOSS'!H6 -> 0.038074713 | K11: =D72 -> 0.035 | L11: =E72 -> 0.035 | M11: =F72 -> 0.035 | N11: =G72 -> 0.035 | O11: =H72 -> 0.035 | R11: =D73 -> 0.0334 | S11: =E73 -> 0.0334 | T11: =F73 -> 0.0334 | U11: =G73 -> 0.0334 | V11: =H73 -> 0.0334 | Y11: =D74 -> 0.032 | Z11: =E74 -> 0.032 | AA11: =F74 -> 0.032 | AB11: =G74 -> 0.032 | AC11: =H74 -> 0.032
B12: Disposals | C12: ₹ | D12: =SUM(D9:D10)-D15 -> 1770 | E12: =SUM(E9:E10)-E15 -> 2405 | F12: =SUM(F9:F10)-F15 -> 2709 | G12: =SUM(G9:G10)-G15 -> 3699 | H12: =SUM(H9:H10)-H15 -> 2621 | K12: =K9*K13 -> 2590.145 | L12: =L9*L13 -> 2654.4433 | M12: =M9*M13 -> 2714.969 | N12: =N9*N13 -> 2775.8499 | O12: =O9*O13 -> 2837.1916 | R12: =R9*R13 -> 2702.76 | S12: =S9*S13 -> 2731.9229 | T12: =T9*T13 -> 2754.0512 | U12: =U9*U13 -> 2777.0238 | V12: =V9*V13 -> 2800.7742 | Y12: =Y9*Y13 -> 2815.375 | Z12: =Z9*Z13 -> 2814.4598 | AA12: =AA9*AA13 -> 2808.394 | AB12: =AB9*AB13 -> 2799.6289 | AC12: =AC9*AC13 -> 2788.5367
B13: % of Gross PPE | C13: % | D13: =D12/D9 -> 0.096221799 | E13: =E12/E9 -> 0.12084213 | F13: =F12/F9 -> 0.12622897 | G13: =G12/G9 -> 0.16177564 | H13: =H12/H9 -> 0.12049467 | K13: =K72 -> 0.115 | L13: =L72 -> 0.115 | M13: =M72 -> 0.115 | N13: =N72 -> 0.115 | O13: =O72 -> 0.115 | R13: =K73 -> 0.12 | S13: =L73 -> 0.12 | T13: =M73 -> 0.12 | U13: =N73 -> 0.12 | V13: =O73 -> 0.12 | Y13: =K74 -> 0.125 | Z13: =L74 -> 0.125 | AA13: =M74 -> 0.125 | AB13: =N74 -> 0.125 | AC13: =O74 -> 0.125
B15: Closing Gross PPE | C15: ₹ | D15: =D16+D18 -> 19902 | E15: =E16+E18 -> 21461 | F15: =F16+F18 -> 22865 | G15: =G16+G18 -> 21752 | H15: =H16+H18 -> 22523 | K15: =K9+K10-K12 -> 23082.116 | L15: =L9+L10-L12 -> 23608.426 | M15: =M9+M10-M12 -> 24137.825 | N15: =N9+N10-N12 -> 24671.231 | O15: =O9+O10-O12 -> 25242.573 | R15: =R9+R10-R12 -> 22766.024 | S15: =S9+S10-S12 -> 22950.427 | T15: =T9+T10-T12 -> 23141.865 | U15: =U9+U10-U12 -> 23339.785 | V15: =V9+V10-V12 -> 23573.454 | Y15: =Y9+Y10-Y12 -> 22515.679 | Z15: =Z9+Z10-Z12 -> 22467.152 | AA15: =AA9+AA10-AA12 -> 22397.032 | AB15: =AB9+AB10-AB12 -> 22308.293 | AC15: =AC9+AC10-AC12 -> 22257.757
B16: Closing Accumulated Depreciation | C16: ₹ | D16: ='P & L ASSUMPTIONS'!D$75 -> 13327 | E16: ='P & L ASSUMPTIONS'!E$75 -> 14000 | F16: ='P & L ASSUMPTIONS'!F$75 -> 14631 | G16: ='P & L ASSUMPTIONS'!G$75 -> 14339 | H16: ='P & L ASSUMPTIONS'!H$75 -> 14676 | K16: ='P & L ASSUMPTIONS'!K75 -> 15292.45 | L16: ='P & L ASSUMPTIONS'!L75 -> 14914.566 | M16: ='P & L ASSUMPTIONS'!M75 -> 15230.159 | N16: ='P & L ASSUMPTIONS'!N75 -> 15550.771 | O16: ='P & L ASSUMPTIONS'!O75 -> 16014.683 | R16: ='P & L ASSUMPTIONS'!R75 -> 15179.835 | S16: ='P & L ASSUMPTIONS'!S75 -> 14576.22 | T16: ='P & L ASSUMPTIONS'!T75 -> 14699.759 | U16: ='P & L ASSUMPTIONS'!U75 -> 14825.469 | V16: ='P & L ASSUMPTIONS'!V75 -> 15086.928 | Y16: ='P & L ASSUMPTIONS'!Y75 -> 14841.99 | Z16: ='P & L ASSUMPTIONS'!Z75 -> 14598.732 | AA16: ='P & L ASSUMPTIONS'!AA75 -> 14504.128 | AB16: ='P & L ASSUMPTIONS'!AB75 -> 14408.997 | AC16: ='P & L ASSUMPTIONS'!AC75 -> 14583.099
B18: Net PPE | C18: ₹ | D18: ='BALANCE SHEET'!D25 -> 6575 | E18: ='BALANCE SHEET'!E25 -> 7461 | F18: ='BALANCE SHEET'!F25 -> 8234 | G18: ='BALANCE SHEET'!G25 -> 7413 | H18: ='BALANCE SHEET'!H25 -> 7847 | K18: =K15-K16 -> 7789.6658 | L18: =L15-L16 -> 8693.8595 | M18: =M15-M16 -> 8907.6667 | N18: =N15-N16 -> 9120.4608 | O18: =O15-O16 -> 9227.8899 | R18: =R15-R16 -> 7586.1888 | S18: =S15-S16 -> 8374.2068 | T18: =T15-T16 -> 8442.1058 | U18: =U15-U16 -> 8514.3166 | V18: =V15-V16 -> 8486.5263 | Y18: =Y15-Y16 -> 7673.6888 | Z18: =Z15-Z16 -> 7868.42 | AA18: =AA15-AA16 -> 7892.9039 | AB18: =AB15-AB16 -> 7899.296 | AC18: =AC15-AC16 -> 7674.6575
B20: OTHER ASSETS | K20: OTHER ASSETS - FORECAST (BEST CASE) | R20: OTHER ASSETS - FORECAST (BASE CASE) | Y20: OTHER ASSETS - FORECAST (WORST CASE)
B23: Unbilled Receivables | C23: ₹ | D23: ='BALANCE SHEET'!D14 -> 2712 | E23: ='BALANCE SHEET'!E14 -> 6081 | F23: ='BALANCE SHEET'!F14 -> 6052 | G23: ='BALANCE SHEET'!G14 -> 5835 | H23: ='BALANCE SHEET'!H14 -> 6428 | K23: ='P & L ASSUMPTIONS'!K22*'BALANCE SHEET ASSUMPTION'!K24 -> 5398.7328 | L23: ='P & L ASSUMPTIONS'!L22*'BALANCE SHEET ASSUMPTION'!L24 -> 5452.7201 | M23: ='P & L ASSUMPTIONS'!M22*'BALANCE SHEET ASSUMPTION'!M24 -> 5561.7745 | N23: ='P & L ASSUMPTIONS'!N22*'BALANCE SHEET ASSUMPTION'!N24 -> 5673.01 | O23: ='P & L ASSUMPTIONS'!O22*'BALANCE SHEET ASSUMPTION'!O24 -> 5843.2003 | R23: ='P & L ASSUMPTIONS'!R22*'BALANCE SHEET ASSUMPTION'!R24 -> 5706.3537 | S23: ='P & L ASSUMPTIONS'!S22*'BALANCE SHEET ASSUMPTION'!S24 -> 5649.2901 | T23: ='P & L ASSUMPTIONS'!T22*'BALANCE SHEET ASSUMPTION'!T24 -> 5705.783 | U23: ='P & L ASSUMPTIONS'!U22*'BALANCE SHEET ASSUMPTION'!U24 -> 5762.8409 | V23: ='P & L ASSUMPTIONS'!V22*'BALANCE SHEET ASSUMPTION'!V24 -> 5878.0977 | Y23: ='P & L ASSUMPTIONS'!Y22*'BALANCE SHEET ASSUMPTION'!Y24 -> 6230.3693 | Z23: ='P & L ASSUMPTIONS'!Z22*'BALANCE SHEET ASSUMPTION'!Z24 -> 6136.9137 | AA23: ='P & L ASSUMPTIONS'!AA22*'BALANCE SHEET ASSUMPTION'!AA24 -> 6075.5446 | AB23: ='P & L ASSUMPTIONS'!AB22*'BALANCE SHEET ASSUMPTION'!AB24 -> 6014.7892 | AC23: ='P & L ASSUMPTIONS'!AC22*'BALANCE SHEET ASSUMPTION'!AC24 -> 6074.937
B24: % of Rev from OP | C24: % | D24: =D23/'PROFIT & LOSS'!D6 -> 0.043571165 | E24: =E23/'PROFIT & LOSS'!E6 -> 0.076462674 | F24: =F23/'PROFIT & LOSS'!F6 -> 0.066553032 | G24: =G23/'PROFIT & LOSS'!G6 -> 0.06498207 | H24: =H23/'PROFIT & LOSS'!H6 -> 0.072153376 | K24: 0.06 | L24: 0.06 | M24: 0.06 | N24: 0.06 | O24: 0.06 | R24: 0.0647 | S24: 0.0647 | T24: 0.0647 | U24: 0.0647 | V24: 0.0647 | Y24: 0.071 | Z24: 0.071 | AA24: 0.071 | AB24: 0.071 | AC24: 0.071
B26: Other Financial Assets | C26: ₹ | D26: ='BALANCE SHEET'!D16+'BALANCE SHEET'!D32 -> 1354 | E26: ='BALANCE SHEET'!E16+'BALANCE SHEET'!E32 -> 4899 | F26: ='BALANCE SHEET'!F16+'BALANCE SHEET'!F32 -> 1543 | G26: ='BALANCE SHEET'!G16+'BALANCE SHEET'!G32 -> 1609 | H26: ='BALANCE SHEET'!H16+'BALANCE SHEET'!H32 -> 1311 | K26: =K41*K27 -> 1881.9184 | L26: =L41*L27 -> 1904.8546 | M26: =M41*M27 -> 1946.443 | N26: =N41*N27 -> 1989.0726 | O26: =O41*O27 -> 2051.6868 | R26: =R41*R27 -> 1522.5428 | S26: =S41*S27 -> 1511.3548 | T26: =T41*T27 -> 1529.2945 | U26: =U41*U27 -> 1547.555 | V26: =V41*V27 -> 1580.843 | Y26: =Y41*Y27 -> 1285.0746 | Z26: =Z41*Z27 -> 1268.9087 | AA26: =AA41*AA27 -> 1259.1603 | AB26: =AB41*AB27 -> 1249.627 | AC26: =AC41*AC27 -> 1264.0316
B27: % of TI | C27: % | D27: =D26/D41 -> 0.020951644 | E27: =E26/E41 -> 0.060044123 | F27: =F26/F41 -> 0.016555616 | G27: =G26/G41 -> 0.01740871 | H27: =H26/H41 -> 0.01410102 | K27: =Y72 -> 0.02 | L27: =Z72 -> 0.02 | M27: =AA72 -> 0.02 | N27: =AB72 -> 0.02 | O27: =AC72 -> 0.02 | R27: =Y73 -> 0.0165 | S27: =Z73 -> 0.0165 | T27: =AA73 -> 0.0165 | U27: =AB73 -> 0.0165 | V27: =AC73 -> 0.0165 | Y27: =Y74 -> 0.014 | Z27: =Z74 -> 0.014 | AA27: =AA74 -> 0.014 | AB27: =AB74 -> 0.014 | AC27: =AC74 -> 0.014
B28: Current Financial Assets | C28: ₹ | D28: ='BALANCE SHEET'!D16 -> 745 | E28: ='BALANCE SHEET'!E16 -> 4291 | F28: ='BALANCE SHEET'!F16 -> 910 | G28: ='BALANCE SHEET'!G16 -> 1054 | H28: ='BALANCE SHEET'!H16 -> 845 | K28: =K26*K29 -> 1129.151 | L28: =L26*L29 -> 1142.9128 | M28: =M26*M29 -> 1167.8658 | N28: =N26*N29 -> 1193.4435 | O28: =O26*O29 -> 1231.0121 | R28: =R26*R29 -> 989.65281 | S28: =S26*S29 -> 982.3806 | T28: =T26*T29 -> 994.04143 | U28: =U26*U29 -> 1005.9107 | V28: =V26*V29 -> 1027.5479 | Y28: =Y26*Y29 -> 899.55219 | Z28: =Z26*Z29 -> 888.23612 | AA28: =AA26*AA29 -> 881.41222 | AB28: =AB26*AB29 -> 874.73889 | AC28: =AC26*AC29 -> 884.82214
B29: % of Total Financial Assets | C29: % | D29: =D28/D26 -> 0.55022157 | E29: =E28/E26 -> 0.87589304 | F29: =F28/F26 -> 0.58976021 | G29: =G28/G26 -> 0.65506526 | H29: =H28/H26 -> 0.64454615 | K29: =100%-K31 -> 0.6 | L29: =100%-L31 -> 0.6 | M29: =100%-M31 -> 0.6 | N29: =100%-N31 -> 0.6 | O29: =100%-O31 -> 0.6 | R29: =100%-R31 -> 0.65 | S29: =100%-S31 -> 0.65 | T29: =100%-T31 -> 0.65 | U29: =100%-U31 -> 0.65 | V29: =100%-V31 -> 0.65 | Y29: =100%-Y31 -> 0.7 | Z29: =100%-Z31 -> 0.7 | AA29: =100%-AA31 -> 0.7 | AB29: =100%-AB31 -> 0.7 | AC29: =100%-AC31 -> 0.7
B30: Non Current Financial Assets | C30: ₹ | D30: ='BALANCE SHEET'!D32 -> 609 | E30: ='BALANCE SHEET'!E32 -> 608 | F30: ='BALANCE SHEET'!F32 -> 633 | G30: ='BALANCE SHEET'!G32 -> 555 | H30: ='BALANCE SHEET'!H32 -> 466 | K30: =K26*K31 -> 752.76736 | L30: =L26*L31 -> 761.94185 | M30: =M26*M31 -> 778.57719 | N30: =N26*N31 -> 795.62902 | O30: =O26*O31 -> 820.67472 | R30: =R26*R31 -> 532.88997 | S30: =S26*S31 -> 528.97417 | T30: =T26*T31 -> 535.25308 | U30: =U26*U31 -> 541.64424 | V30: =V26*V31 -> 553.29504 | Y30: =Y26*Y31 -> 385.52237 | Z30: =Z26*Z31 -> 380.67262 | AA30: =AA26*AA31 -> 377.74809 | AB30: =AB26*AB31 -> 374.8881 | AC30: =AC26*AC31 -> 379.20949
B31: % of Total Financial Assets | C31: % | D31: =D30/D26 -> 0.44977843 | E31: =E30/E26 -> 0.12410696 | F31: =F30/F26 -> 0.41023979 | G31: =G30/G26 -> 0.34493474 | H31: =H30/H26 -> 0.35545385 | K31: 0.4 | L31: 0.4 | M31: 0.4 | N31: 0.4 | O31: 0.4 | R31: 0.35 | S31: 0.35 | T31: 0.35 | U31: 0.35 | V31: 0.35 | Y31: 0.3 | Z31: 0.3 | AA31: 0.3 | AB31: 0.3 | AC31: 0.3
B33: Current Tax Assets | C33: ₹ | D33: ='BALANCE SHEET'!D17 -> 246 | E33: ='BALANCE SHEET'!E17 -> 237 | F33: ='BALANCE SHEET'!F17 -> 509 | G33: ='BALANCE SHEET'!G17 -> 648 | H33: ='BALANCE SHEET'!H17 -> 642 | K33: =R$33+50 -> 650 | L33: =S$33+50 -> 680 | M33: =T$33+50 -> 710 | N33: =U$33+50 -> 740 | O33: =V$33+50 -> 770 | R33: 600 | S33: =R33+30 -> 630 | T33: =S33+30 -> 660 | U33: =T33+30 -> 690 | V33: =U33+30 -> 720 | Y33: =R33+10 -> 610 | Z33: =Y33+10 -> 620 | AA33: =Z33+10 -> 630 | AB33: =AA33+10 -> 640 | AC33: =AB33+10 -> 650
